<?xml version="1.0"?>
<robot xmlns:sensor="http://playerstage.sourceforge.net/gazebo/xmlschema/#sensor"
       xmlns:controller="http://playerstage.sourceforge.net/gazebo/xmlschema/#controller"
       xmlns:interface="http://playerstage.sourceforge.net/gazebo/xmlschema/#interface"
       xmlns:xacro="http://playerstage.sourceforge.net/gazebo/xmlschema/#interface">

  <macro name="m3_shoulder" params="side lr parent reflect rotate *origin">

    <!-- Shoulder pan -->
    <joint name="${lr}_arm_j0" type="revolute">
      <axis xyz="0 -1 0" />
      <insert_block name="origin" /> <!-- transform from parent link to this joint frame -->
      <parent link="${parent}"/>
      <child link="shoulderupper_${lr}"/>
      <limit effort="40" velocity="${30.0*M_PI/180}" lower="${-80*M_PI/180}" upper="${200*M_PI/180}" />
      <dynamics damping="1.0"/>
    </joint>
    
    <link name="shoulderupper_${lr}">
      <inertial>
        <mass value="2.0310" />
	    <inertia ixx="0.003461" ixy="0.000428" ixz="0.000002"
	             iyy="0.003097" iyz="0.000000" 
	             izz="0.005416" />
      </inertial>
      <visual>
	      <material name="GreyA" />
	      <origin xyz="0 0 0" rpy="${rotate*M_PI} 0 0 " />
	      <geometry name="${lr}_shoulder_geom">
		      <mesh filename="package://${MESH}/A2R3/A2R3_RT1_shoulderRoll.dae" />
	      </geometry>  
      </visual>
      <!-- meshes
      <collision>
	      <origin xyz="0 0 0" rpy="0.0 0.0 0.0 " />
	      <geometry name="r_shoulder_collision_geom">
		      <mesh filename="package://${MESH_COLL}/A2R3/A2R3_RT1_shoulderRoll.stl" />
	      </geometry>
      </collision> -->  
      <!-- primitive only -->
      <collision>
        <origin xyz="0.0 ${reflect*0.035} 0.0" rpy="0.0 0.0 0.0 " />
        <geometry>
          <box size="0.128 0.07 0.072" />
        </geometry>
      </collision>
      <collision>
        <origin xyz="-0.011 0.0 0" rpy="0 1.5707 0.0 " />
        <geometry>
          <cylinder radius="0.036" length="0.15" />
        </geometry>
      </collision>
    </link>

    <joint name="${lr}_arm_j1" type="revolute">
      <axis xyz="-1 0 0"/>
     <limit effort="40" velocity="${30*M_PI/180}" lower="${-24*M_PI/180}" upper="${150*M_PI/180}" />    
      <origin xyz="0 0 0" rpy="0 0 0" />
      <parent link="shoulderupper_${lr}"/>
      <child link="shoulderpitch_${lr}"/>
      <dynamics damping="1.0"/>
    </joint>
    
    <link name="shoulderpitch_${lr}">
      <inertial>
        <mass value="0.566" />
        <origin xyz="0.000944 ${reflect*-0.026331} -0.043257" rpy="0 0 0"/>
	    <inertia ixx="0.000754" ixy="0.000015" ixz="0.000014"
	             iyy="0.000921" iyz="0.000142"
	             izz="0.000834" />
      </inertial>
      <visual>
	      <material name="GreyB" />
	      <origin xyz="0 0 0" rpy="0 0 ${rotate*M_PI}" />
	      <geometry name="shoulderpitch_${lr}">
		      <mesh filename="package://${MESH}/A2R3/A2R3_RT2_shoulderPitch.dae" />		      
	      </geometry>  
      </visual>
      <!-- meshes
      <collision>
	      <origin xyz="0 0 0" rpy="0.0 0.0 0.0 " />
	      <geometry name="shoulderpitch_${lr}_collision">
		      <mesh filename="package://${MESH_COLL}/A2R3/A2R3_RT2_shoulderPitch.stl" />
	      </geometry>
      </collision>
      -->  
      <!-- primitive only -->
      <collision>
        <origin xyz="0.0 ${reflect*-0.0256} -0.04" rpy="-0.58 0.0 0.0 " />
        <geometry>
          <box size="0.09 0.07 0.072" />
        </geometry>
      </collision>
      <collision>
        <origin xyz="0 ${reflect*-0.0319} -0.0595" rpy="0 0 0.0 " />
        <geometry>
          <cylinder radius="0.04" length="0.0262" />
        </geometry>
      </collision>
      <collision>
        <origin xyz="-0.0407 0.0 0" rpy="0 1.5707 0.0 " />
        <geometry>
          <cylinder radius="0.0352" length="0.008" />
        </geometry>
      </collision>      
      <collision>
        <origin xyz="0.0407 0.0 0" rpy="0 1.5707 0.0 " />
        <geometry>
          <cylinder radius="0.0352" length="0.008" />
        </geometry>
      </collision>
    </link>

    <joint name="${lr}_arm_j2" type="revolute">
      <axis xyz="0 0 -1" />
      <origin xyz="0 ${reflect*-0.03175} -0.27857" rpy="0 0 0" />
      <parent link="shoulderpitch_${lr}" />
      <child link="bicep_${lr}"/>
      <limit effort="20" velocity="${50*M_PI/180}" lower="${-85*M_PI/180}" upper="${85*M_PI/180}" />    
      <dynamics damping="1.0"/>
    </joint>
    
    <link name="bicep_${lr}">
      <xacro:inertial_cuboid_with_pose mass="2.296" x_length="0.1" y_length="0.07" z_length="0.25">
          <origin xyz="-0.005767 ${reflect*-0.001385} 0.084539 "/>
      </xacro:inertial_cuboid_with_pose>       
      <visual>
	      <material name="GreyC" />
	      <origin xyz="0.00502 0 0" rpy="0 0 0 " />
	      <geometry name="bicep_${lr}_geom">
		      <mesh filename="package://${MESH}/A2R3/A2R3_${side}T3_bicep.dae" />
	      </geometry>  
      </visual>
      <!-- meshes 
      <collision>
	      <origin xyz="0 0 0" rpy="0.0 0.0 0.0 " />
	      <geometry name="bicep_${lr}_geom_collision">
		      <mesh filename="package://${MESH_COLL}/A2R3/A2R3_RT3_bicep.stl" />
	      </geometry>
      </collision> -->  
      <!-- primitive only -->
      <collision>
        <origin xyz="-0.03 0 0.1" rpy="0 0.0 0.0 " />
        <geometry>
          <box size="0.07 0.08 0.15" />
        </geometry>
      </collision>
      <collision>
        <origin xyz="-0.0047 0 0.15" rpy="0 0 0.0 " />
        <geometry>
          <cylinder radius="0.04" length="0.12" />
        </geometry>
      </collision>
      <collision>
        <origin xyz="0 0.0 0"  rpy="1.5707 0.0 0.0 " />
        <geometry>
          <cylinder radius="0.0362" length="0.077" />
        </geometry>
      </collision>
    </link>

  </macro>

  <!-- ============================   Upper Arm   ============================ -->

  <macro name="m3_upper_arm" params="side lr parent reflect rotate">

	  <joint name="${lr}_arm_j3" type="revolute">
		  <axis xyz="0 -1 0" />
		  <origin xyz="0.00502 0  0" rpy="0 0 0" />
      <parent link="${parent}"/>
      <child link="elbowclevis_${lr}"/>
	<limit effort="20" velocity="${50*M_PI/180}" lower="${-0.278978*M_PI/180}" upper="${132.8175*M_PI/180}" />    
      <dynamics damping="10.0" />
    </joint>
    
    <link name="elbowclevis_${lr}">
      <inertial>       
        <mass value="0.223" />
        <origin xyz="-0.000002 ${reflect*0.000278} -0.026124"/>
	    <inertia ixx="0.000470" ixy="0.000000" ixz="0.000000"
	             iyy="0.000233" iyz="0.000019"
	             izz="0.000425" />
      </inertial>
      <visual>
	      <material name="GreyA" />
	      <origin xyz="0 0 0" rpy="0 0 ${rotate*M_PI} " />
	      <geometry name="elbowclevis_${lr}_geom">
		      <mesh filename="package://${MESH}/A2R3/A2R3_RT4_elbow.dae" />
	      </geometry>  
      </visual>
      <!-- meshes 
      <collision>
	      <origin xyz="0 0 0" rpy="0.0 0.0 0.0 " />
	      <geometry name="elbowclevis_${lr}_collision">
		      <mesh filename="package://${MESH_COLL}/A2R3/A2R3_RT4_elbow.stl" />
	      </geometry>
      </collision> -->  
      <!-- primitive only -->
      <collision>
        <origin xyz="0 0 -0.048" rpy="0 0.0 0.0 " />
        <geometry>
          <box size="0.0712 0.0868 0.015" />
        </geometry>
      </collision>
       <collision>
        <origin xyz="0 ${reflect*0.0443} -0.024" rpy="0 0 0.0 " />
        <geometry>
          <box size="0.0652 0.01 0.048" />
        </geometry>
      </collision>
       <collision>
       <origin xyz="0 ${reflect*-0.046} -0.024" rpy="0 0 0.0 " />
        <geometry>
          <box size="0.0652 0.01 0.048" />
        </geometry>
      </collision>  
      <collision>
        <origin xyz="0 ${reflect*0.0443} 0" rpy="1.5707 0 0.0 " />
        <geometry>
          <cylinder radius="0.0356" length="0.01" />
        </geometry>
      </collision>
      <collision>
        <origin xyz="0 ${reflect*-0.0485} 0" rpy="1.5707 0 0.0 " />
        <geometry>
          <cylinder radius="0.0356" length="0.015" />
        </geometry>
      </collision>
    </link>

    <joint name="${lr}_arm_j4" type="revolute">
	    <axis xyz="0 0 -1" />
      <limit effort="4" velocity="${150*M_PI/180}" lower="${-19.7*M_PI/180}" upper="${199.7*M_PI/180}" /> 
      <origin xyz="0 0 -0.27747" rpy="0 0 0" />
      <parent link="elbowclevis_${lr}"/>
      <child link="wrist_${lr}"/>
      <dynamics damping="1.0"/>
    </joint>
    
    <link name="wrist_${lr}">
      <inertial>
        <mass value="1.468" />
        <origin xyz="-0.004404 ${reflect*0.000124} 0.130931"/>
	    <inertia ixx="0.006099" ixy="0.000004" ixz="-0.000043"
	             iyy="0.006120" iyz="0.000015"
	             izz="0.001179" />
      </inertial>
      <visual>
	      <material name="GreyC" />
	      <origin xyz="0 0 0" rpy="0 0 0 " />
	      <geometry name="wrist_${lr}_geom">
		      <mesh filename="package://${MESH}/A2R3/A2R3_T5_forearmRoll.dae" />
	      </geometry>  
      </visual>
      <!-- meshes
      <collision>
	      <origin xyz="0 0 0" rpy="0.0 0.0 0.0 " />
	      <geometry name="wrist_${lr}_collision">
		      <mesh filename="package://${MESH_COLL}/A2R3/A2R3_T5_forearmRoll.stl" />
	      </geometry>
      </collision>
       -->  
      <!-- primitive only -->
      <collision>
        <origin xyz="0.0 0 0.1317" rpy="0 0.0 0.0 " />
        <geometry>
            <cylinder radius="0.041" length="0.18" />
        </geometry>
      </collision>
      <collision>
        <origin xyz="0 0.0307 0.025"  rpy="0.0 0.0 0.0 " />
        <geometry>
          <box size="0.03 0.0154 0.05" />
        </geometry>
      </collision>
      <collision>
        <origin xyz="0 -0.0307 0.025"  rpy="0.0 0.0 0.0 " />
        <geometry>
          <box size="0.03 0.0154 0.05" />
        </geometry>
      </collision>     
      <collision>
        <origin xyz="0 0.027 0"  rpy="1.5707 0.0 0.0 " />
        <geometry>
          <cylinder radius="0.024" length="0.007" />
        </geometry>
      </collision>
      <collision>
        <origin xyz="0 -0.027 0"  rpy="1.5707 0.0 0.0 " />
        <geometry>
          <cylinder radius="0.024" length="0.007" />
        </geometry>
      </collision>
      
    </link> 

  </macro>

  <!-- ============================   Forearm   ============================ -->

  <macro name="m3_forearm" params="side lr parent reflect rotate">

    <joint name="${lr}_arm_j5" type="revolute">
      <axis xyz="0 -1 0" />
      <origin xyz="0 0 0" rpy="0 0 0" />
      <parent link="${parent}"/>
      <child link="w_differential_${lr}"/>
	  <limit effort="8" velocity="${40*M_PI/180}" lower="${-58.83*M_PI/180}" upper="${58.83*M_PI/180}" /> 
      <dynamics damping="1.0"/>
    </joint>
    
    <link name="w_differential_${lr}">
      <inertial>
        <mass value="0.278" />
        <origin xyz="0 0 0" />
        <inertia ixx="0" ixy="0" ixz="0"
                 iyy="0" iyz="0"
                 izz="0" />
      </inertial>
      <visual>
	      <material name="GreyB" />
	      <origin xyz="0 0 0" rpy="0 0 0 " />
	      <geometry name="w_differential_${lr}_geom">
		      <mesh filename="package://${MESH}/A2R3/A2R3_T6_wristDiff.dae" />
	      </geometry>  
      </visual>
      <collision>
	      <origin xyz="0 0 0" rpy="1.5707 0.0 0.0" />
	      <geometry name="w_differential_${lr}_collision">
		      <cylinder radius="0.027" length="0.044" />
	      </geometry>
      </collision>
    </link>

    <joint name="${lr}_arm_j6" type="revolute">
	    <axis xyz="-1 0 0" />
      <limit effort="8" velocity="${40*M_PI/180}" lower="${-60*M_PI/180}" upper="${60*M_PI/180}" /> 
      <origin xyz="0 0 0" rpy="0 0 0" />
      <parent link="w_differential_${lr}"/>
      <child link="handmount_${lr}"/>
      <dynamics damping="1.0"/>
    </joint>
    
    <link name="handmount_${lr}">
      <inertial>
        <mass value="0.093" />
        <origin xyz="0 0 0" />
        <inertia ixx="0" ixy="0" ixz="0"
                 iyy="0" iyz="0"
                 izz="0" />
      </inertial>
      <visual>
	      <material name="GreyA" />
	      <origin xyz="0 0 0" rpy="0 0 0 " />
	      <geometry name="handmount_${lr}_geom">
		       <mesh filename="package://${MESH}/A2R3/A2R3_T7_wristYaw.dae" />
	      </geometry>  
      </visual>
      <!-- meshes
      <collision>
	      <origin xyz="0 0 0" rpy="0.0 0.0 0.0 " />
	      <geometry name="handmount_${lr}_collision">
		      <mesh filename="package://${MESH_COLL}/A2R3/A2R3_T7_wristYaw.stl" />
	      </geometry>
      </collision>
       -->  
      <!-- primitive only -->
      <collision>
        <origin xyz="0 0 -0.043"  rpy="0.0 0.0 0.0 " />
        <geometry>
          <box size="0.04 0.0412 0.004" />
        </geometry>
      </collision>
      <collision>
        <origin xyz="-0.025 0.0 -0.0302"  rpy="0 1.1 0.0" />
        <geometry>
          <box size="0.03 0.03 0.004" />
        </geometry>
      </collision>
      <collision>
        <origin xyz="0.025 0.0 -0.0302"  rpy="0 2.04 0.0" />
        <geometry>
          <box size="0.03 0.03 0.004" />
        </geometry>
      </collision>    
      <collision>
        <origin xyz="-0.0275 0.0 0"  rpy="0 1.5707 0.0" />
        <geometry>
          <cylinder radius="0.0206" length="0.014" />
        </geometry>
      </collision>
      <collision>
        <origin xyz="0.0275 0.0 0"  rpy="0 1.5707 0.0" />
        <geometry>
          <cylinder radius="0.0206" length="0.014" />
        </geometry>
      </collision>
    </link>

  </macro>

  <macro name="m3_arm" params="side lr parent reflect rotate *origin">
    <m3_shoulder side="${side}" lr="${lr}" reflect="${reflect}" rotate="${rotate}" parent="${parent}">
      <insert_block name="origin" />
    </m3_shoulder>
    <m3_upper_arm side="${side}" lr="${lr}" reflect="${reflect}" rotate="${rotate}" parent="bicep_${lr}" />
    <m3_forearm side="${side}" lr="${lr}" reflect="${reflect}" rotate="${rotate}" parent="wrist_${lr}" />
    <m3_arm_transmission lr="${lr}"/>
  </macro>
  
</robot>
