<?xml version="1.0"?>
<robot xmlns:sensor="http://playerstage.sourceforge.net/gazebo/xmlschema/#sensor"
       xmlns:controller="http://playerstage.sourceforge.net/gazebo/xmlschema/#controller"
       xmlns:interface="http://playerstage.sourceforge.net/gazebo/xmlschema/#interface"
       xmlns:xacro="http://playerstage.sourceforge.net/gazebo/xmlschema/#interface">
 
  <xacro:macro name="meka_zlift" params="parent *origin">

    <joint name="zlift_j0" type="prismatic">
      <insert_block name="origin" /> 
      <axis xyz="0 0 1" />
      <parent link="${parent}"/>
      <child link="zlift_link"/>
      <limit lower="${0*M_PI/180}"  upper="${38.9*M_PI/180}"
             effort="30" velocity="${34.8}" /> <!-- !!! this should be changed at some point !!! -->

      <dynamics damping="10.0" />

      <!--safety_controller k_position="100" k_velocity="10"
                         soft_lower_limit="${reflect*M_PI/4-1.5+0.15}"
                         soft_upper_limit="${reflect*M_PI/4+1.5-0.15}" /-->      
    </joint>
    
    <link name="zlift_link">
       <xacro:inertial_cuboid_with_pose mass="10.0" x_length="0.07" y_length="0.1" z_length="0.166">
          <origin xyz="0.0 0.0 0.0" rpy="0 0 0"/>
      </xacro:inertial_cuboid_with_pose> 
      <visual>
	      <material name="GreyA" />
	      <origin xyz="0 0 0" rpy="0 0 0 " />
	      <geometry name="z_lift_geom">
		      <mesh filename="package://${MESH}/B1R1/meka_festo-chest_mount_assy.dae" />
	      </geometry>  
      </visual>
      <!-- meshes 
      <collision>
	      <origin xyz="0 0 0" rpy="0.0 0.0 0.0 " />
	      <geometry name="z_lift_geom_collision_geom">
		      <mesh filename="package://${MESH_COLL}/B1R1/MB1_00_011_festo-chest_mount_assy+spacer.stl" />
	      </geometry>
      </collision>-->
      <!-- primitive meshes only -->
    <collision>
		  <origin xyz="0.108 0 0.035" rpy="0.0 0.0 0.0 " />
		  <geometry>
			  <box size="0.2 0.21 0.07" />
		  </geometry>
	  </collision>
    <collision>
		  <origin xyz="0.004 0 0.09" rpy="0.0 0.0 0.0 " />
		  <geometry>
			  <box size="0.008 0.08 0.18" />
		  </geometry>
	  </collision>
    </link>
    
  </xacro:macro>

</robot>
