<?xml version="1.0"?>
<robot xmlns:sensor="http://playerstage.sourceforge.net/gazebo/xmlschema/#sensor"
       xmlns:controller="http://playerstage.sourceforge.net/gazebo/xmlschema/#controller"
       xmlns:interface="http://playerstage.sourceforge.net/gazebo/xmlschema/#interface"
       xmlns:xacro="http://playerstage.sourceforge.net/gazebo/xmlschema/#interface"
       name="meka" >

 <property name="M_PI" value="3.1415926535897931" />
 <property name="MESH" value="meka_description/meshes/mid_res" />
 <property name="MESH_COLL" value="meka_description/meshes/low_res" />

 <xacro:arg name="use_mimic" default="true"/> 
 <!-- synergy vector -->
 <xacro:property name="torso_coupling" value="1.0" />
 

<!-- generic simulator_gazebo plugins for starting mechanism control, ros time, ros battery -->
  <xacro:include filename="$(find meka_description)/gazebo/gazebo.urdf.xacro" />
  <!--<xacro:include filename="$(find meka_description)/transmissions/uta.transmission.xacro" />-->

<!-- Meka Base -->
  <xacro:include filename="$(find meka_description)/urdf/B1R2B_defs.urdf.xacro" />

<!-- Meka Zlift -->
  <xacro:include filename="$(find meka_description)/urdf/Z1R2B_defs.urdf.xacro" />

<!-- Meka Arm -->
  <xacro:include filename="$(find meka_description)/urdf/A2R4_r_arm_defs.urdf.xacro" />

  <xacro:include filename="$(find meka_description)/urdf/A2R4_l_arm_defs.urdf.xacro" />
  

  <!-- Meka Hand -->
  <xacro:include filename="$(find meka_description)/urdf/H2R4_r_hand_defs.urdf.xacro" />

  <xacro:include filename="$(find meka_description)/urdf/H2R4_l_hand_defs.urdf.xacro" />

  
<!-- Meka Head -->
  <xacro:include filename="$(find meka_description)/urdf/S3R1_head_defs.urdf.xacro" />



  <!-- john added transmissions -->
  <!-- <xacro:include filename="$(find meka_description)/transmissions/A2R4_r_arm_defs.transmission.xacro" /> -->
  <!--<xacro:include filename="$(find meka_description)/transmissions/H2R2_r_hand_defs.transmission.xacro" />-->
  <!--<xacro:include filename="$(find meka_description)/transmissions/S2R1_head_defs.transmission.xacro" />-->


   <property name="M_PI" value="3.1415926535897931" />
  <material name="GreyA"> <!-- darkest -->
    <color rgba="0.3 0.3 0.3 1.0"/>
  </material>
  
  <material name="GreyB">
    <color rgba="0.5 0.5 0.5 1.0"/>
  </material>
  
  <material name="GreyC">
    <color rgba="0.7 0.7 0.7 1.0"/>
  </material>
  


  <!-- john added transmissions -->
  <m3_r_arm_transmission side="r" reflect="1" parent="upper"/>
  <m3_r_hand_transmission/>
  
  <m3_r_hand side="r" reflect="1" parent="handmount_RIGHT" use_mimic="$(arg use_mimic)">
    <origin xyz="0.0 0.0 0.0" rpy="0 0 0" />
  </m3_r_hand>
  
  <m3_l_hand side="l" reflect="1" parent="handmount_LEFT" use_mimic="$(arg use_mimic)">
    <origin xyz="0.0 0.0 0.0" rpy="0 0 0" />
  </m3_l_hand>
 

  <m3_head side="r" reflect="1" parent="upper">
    <origin xyz="0.0 0.0 0.31155" rpy="0 0 0" />
  </m3_head>

 <m3_r_arm side="r" reflect="1" parent="upper">
    <origin xyz="0.0 -0.18465 0.2337" rpy="0 0 0" />
  </m3_r_arm>

 <m3_l_arm side="l" reflect="1" parent="upper">
    <origin xyz="0.0 0.18465 0.2337" rpy="0 0 0" />
  </m3_l_arm>



  <link name="base_link" />

  <meka_base  side="r" reflect="1" parent="base_link">
    <origin xyz="0.0 0.0 0.0" rpy="0 0 0" />
  </meka_base>

  <meka_zlift  side="r" reflect="1" parent="dummy_3">
    <origin xyz="0.43 0.0 0.75" rpy="0 0 0" />
  </meka_zlift>

  <!-- Solid Base -->
  <joint name="chest_joint" type="fixed">
	  <origin xyz="0.1 0.0 0.0" rpy="0 0 0" />
    <parent link="zlift_link" />
    <child link="panplate" />
  </joint>
  
  
  <link name="panplate">
    <inertial>
      <mass value="1000" />
      <origin xyz="0 0 0" />
      <inertia ixx="100"  ixy="0"  ixz="0" iyy="100" iyz="0" izz="100" />
    </inertial>
    <visual>
      <material name="GreyA" />
      <origin xyz="0 0 0" rpy="0 0 0 " />
      <geometry name="panplate_geom">
        <mesh filename="package://${MESH}/T2R3/T2R3_TJ0_base.dae" />
      </geometry>  
    </visual>  
    <!-- meshes  
    <collision>
      <origin xyz="0 0 0" rpy="0.0 0.0 0.0 " />
      <geometry name="base_collision_geom">
        <mesh filename="package://${MESH_COLL}/T2R3/T2R3_TJ0_base.stl" />
      </geometry>
    </collision>-->  
    <!-- primitive only -->
    <collision>
		  <origin xyz="-0.11 0 0.025" rpy="0.0 0.0 0.0 " />
		  <geometry>
			  <box size="0.22 0.19 0.05" />
		  </geometry>
	  </collision>
    <collision>
		  <origin xyz="0.0 0 0.05" rpy="0.0 0.0 0.0 " />
		  <geometry>
			  <cylinder radius="0.095" length="0.1" />
		  </geometry>
	  </collision>
    
  </link>
  <joint name="torso_j0" type="revolute">
    <axis xyz="0 0 1"/>
    <origin xyz="0 0 0.1678" rpy="0 0 0" />
    <parent link="panplate" />
    <child link="torso" />
    <limit effort="25" velocity="${25.0*M_PI/180}" lower="${-120*M_PI/180.0}" upper="${120*M_PI/180}" />
    <dynamics damping="1.0"/>
  </joint>
  <link name="torso">
    <inertial>
      <mass value="4.411" />
      <origin xyz="0.00011774 0.0038073 -0.0522753" />
      <inertia ixx="0.026360"  ixy="-0.0000024"  ixz="-0.0000508" iyy="0.0134266" iyz="0.0006839" izz="0.0229879" />
    </inertial>
    <visual>
      <material name="GreyC" />
      <origin xyz="0 0 0" rpy="0 0 0 " />
      <geometry name="torso_geom">
        <mesh filename="package://${MESH}/T2R3/T2R3_TJ1_pan.dae" />
      </geometry>  
    </visual>
    <!-- meshes  
    <collision>
      <origin xyz="0 0 0" rpy="0.0 0.0 0.0 " />
      <geometry name="torso_collision_geom">
        <mesh filename="package://${MESH_COLL}/T2R3/T2R3_TJ1_pan.stl" />
      </geometry>
    </collision>
    -->  
    <!-- primitive only -->
    <collision>
		  <origin xyz="0.0 0 -0.0615" rpy="0.0 0.0 0.0 " />
		  <geometry>
			  <cylinder radius="0.088" length="0.015" />
		  </geometry>
	  </collision>
    <collision>
		   <origin xyz="0.0 0 -0.0615" rpy="0.0 0.0 0.0 " />
		  <geometry>
			  <box size="0.08 0.23 0.015" />
		  </geometry>
	  </collision>
    <collision>
		  <origin xyz="0.0 0.105 0" rpy="1.5707 0.0 0.0 " />
		  <geometry>
			  <cylinder radius="0.052" length="0.02" />
		  </geometry>
	  </collision>
    <collision>
		  <origin xyz="0.0 -0.105 0" rpy="1.5707 0.0 0.0  " />
		  <geometry>
			  <cylinder radius="0.052" length="0.02" />
		  </geometry>
	  </collision>
  </link>
  
  <joint name="torso_j1" type="revolute">
    <axis xyz="0 1 0"/>
    <origin xyz="0 0 0" rpy="0 0 0" />    
    <parent link="torso" />
    <child link="mid" />
    <limit effort="200" velocity="${10.0*M_PI/180}" lower="${-11.79349*M_PI/180}" upper="${53.29349*M_PI/180}" />
    <dynamics damping="1.0"/>
  </joint>
  <link name="mid">
    <inertial>
      <mass value="4.934" />
      <origin xyz="0.001179 -0.002993 0.046259"/>
      <inertia ixx="0.041106"
      iyy="0.026009"
      izz="0.025902"
      ixy="0.000135"
      ixz="0.000505"
      iyz="0.002396" />
    </inertial>
    <visual>
      <material name="GreyB" />
      <origin xyz="0 0 0" rpy="0 0 0" />
      <geometry name="mid_geom">
        <mesh filename="package://${MESH}/T2R3/T2R3_TJ2.dae" />
      </geometry>
    </visual>
    <!-- meshes  
    <collision>
      <origin xyz="0 0 0" rpy="0.0 0.0 0.0 " />
      <geometry name="mid_collision_geom">
        <mesh filename="package://${MESH_COLL}/T2R3/T2R3_TJ2.stl" />
      </geometry>
    </collision>
    -->  
    <!-- primitive only -->
    <collision>
		  <origin xyz="0.0 0 0.0684" rpy="0.0 0.0 0.0 " />
		  <geometry>
			  <box size="0.114 0.241 0.1368" />
		  </geometry>
	  </collision>
    <collision>
		  <origin xyz="0.0 0.0 0" rpy="1.5707 0.0 0.0 " />
		  <geometry>
			  <cylinder radius="0.057" length="0.241" />
		  </geometry>
	  </collision>
    <collision>
		  <origin xyz="0.0 0.0 0.1368" rpy="1.5707 0.0 0.0 " />
		  <geometry>
			  <cylinder radius="0.057" length="0.241" />
		  </geometry>
	  </collision>
    
  </link>
  
  <joint name="torso_j2" type="revolute">
    <axis xyz="0 1 0"/>
    <origin xyz="0 0 0.1397" rpy="0 0 0" />    
    <parent link="mid" />
    <child link="upper" />
    <limit effort="200" velocity="${10.0*M_PI/180}" lower="${-11.79349*M_PI/180}" upper="${53.29349*M_PI/180}" />
    <dynamics damping="1.0"/>
    <xacro:if value="$(arg use_mimic)">
      <mimic joint="torso_j1" multiplier="${torso_coupling}"/>
		</xacro:if>
  </joint>

  <link name="upper">
    <inertial>
      <mass value="6.534" />
      <origin xyz="0.008700 0.011470 0.129740"/>
      <inertia ixx="0.069760"
      iyy="0.048010"
      izz="0.040590"
      ixy="-0.000400"
      ixz="0.001300"
      iyz="0.005100" />
    </inertial>
    <visual>
      <material name="GreyC" />
      <origin xyz="0 0 0" rpy="0 0 0" />
      <geometry name="upper_geom">
       <mesh filename="package://${MESH}/A2R3/A2R3_T4_Chest_Neck.dae" />
      </geometry>
    </visual>
    <!-- meshes 
    <collision>
      <origin xyz="0 0 0" rpy="0.0 0.0 0.0 " />
      <geometry name="upper_collision_geom">
        <mesh filename="package://${MESH_COLL}/T2R3/T2R3_TJ3_chest_waist_neck.stl" />
      </geometry>
    </collision>
        -->  
    <!-- primitive only -->
    <collision>
		  <origin xyz="0.0 0 0.1346" rpy="0.0 0.0 0.0 " />
		  <geometry>
			  <box size="0.14 0.22 0.1978" />
		  </geometry>
	  </collision>
    <collision>
		  <origin xyz="0.0 0.0 0.2335" rpy="1.5707 0.0 0.0 " />
		  <geometry>
			  <cylinder radius="0.0644" length="0.22" />
		  </geometry>
	  </collision>
    
    
  </link>
  


</robot>
  
