<?xml version="1.0" ?>
<!-- =================================================================================== -->
<!-- |    This document was autogenerated by xacro from bie_sim.urdf.xacro             | -->
<!-- |    EDITING THIS FILE BY HAND IS NOT RECOMMENDED                                 | -->
<!-- =================================================================================== -->
<robot name="meka" xmlns:controller="http://playerstage.sourceforge.net/gazebo/xmlschema/#controller" xmlns:interface="http://playerstage.sourceforge.net/gazebo/xmlschema/#interface" xmlns:sensor="http://playerstage.sourceforge.net/gazebo/xmlschema/#sensor" xmlns:xacro="http://playerstage.sourceforge.net/gazebo/xmlschema/#interface">
  <gazebo>
    <plugin filename="libgazebo_ros_control.so" name="gazebo_ros_control">
      <robotNamespace/>
      <robotSimType>gazebo_ros_control/DefaultRobotHWSim</robotSimType>
      <alwaysOn>true</alwaysOn>
      <updateRate>30.0</updateRate>
    </plugin>
    <!--   
    <plugin name="skid_steer_drive_controller" filename="libgazebo_ros_skid_steer_drive.so">
      <alwaysOn>1</alwaysOn>
      <updateRate>60.0</updateRate>
      <robotNamespace>/</robotNamespace>
      <leftFrontJoint>front_left_wheel_joint</leftFrontJoint>
      <rightFrontJoint>front_right_wheel_joint</rightFrontJoint>
      <leftRearJoint>back_left_wheel_joint</leftRearJoint>
      <rightRearJoint>back_right_wheel_joint</rightRearJoint>
      <wheelSeparation>1</wheelSeparation>
      <wheelDiameter>${2*wheel_radius}</wheelDiameter>
      <torque>1000</torque>
      <broadcastTF>1</broadcastTF>
      <odometryFrame>map</odometryFrame>
      <commandTopic>cmd_vel</commandTopic>
      <odometryTopic>odom</odometryTopic>
      <robotBaseFrame>base_link</robotBaseFrame>
      <covariance_x>0.0001</covariance_x>
      <covariance_y>0.0001</covariance_y>
      <covariance_z>0.0001</covariance_z>
      <covariance_yaw>0.0001</covariance_yaw>
    </plugin> -->
    <plugin filename="libgazebo_ros_planar_move.so" name="drive_controller">
      <odometryRate>60.0</odometryRate>
      <robotNamespace>/</robotNamespace>
      <commandTopic>cmd_vel</commandTopic>
      <robotBaseFrame>base_footprint</robotBaseFrame>
    </plugin>
    <plugin filename="libroboticsgroup_gazebo_mimic_joint_plugin.so" name="mimic_right_j1a">
      <joint>right_hand_j1</joint>
      <mimicJoint>right_hand_j1a</mimicJoint>
      <multiplier>0.4</multiplier>
      <sensitiveness>0.0</sensitiveness>
    </plugin>
    <plugin filename="libroboticsgroup_gazebo_mimic_joint_plugin.so" name="mimic_right_j1b">
      <joint>right_hand_j1</joint>
      <mimicJoint>right_hand_j1b</mimicJoint>
      <multiplier>0.4</multiplier>
      <sensitiveness>0.0</sensitiveness>
    </plugin>
    <!-- j2 -->
    <plugin filename="libroboticsgroup_gazebo_mimic_joint_plugin.so" name="mimic_right_j2a">
      <joint>right_hand_j2</joint>
      <mimicJoint>right_hand_j2a</mimicJoint>
      <multiplier>0.3</multiplier>
      <sensitiveness>0.0</sensitiveness>
    </plugin>
    <plugin filename="libroboticsgroup_gazebo_mimic_joint_plugin.so" name="mimic_right_j2b">
      <joint>right_hand_j2</joint>
      <mimicJoint>right_hand_j2b</mimicJoint>
      <multiplier>0.3</multiplier>
      <sensitiveness>0.0</sensitiveness>
    </plugin>
    <plugin filename="libroboticsgroup_gazebo_mimic_joint_plugin.so" name="mimic_right_j2c">
      <joint>right_hand_j2</joint>
      <mimicJoint>right_hand_j2c</mimicJoint>
      <multiplier>0.3</multiplier>
      <sensitiveness>0.0</sensitiveness>
    </plugin>
    <!-- j3 -->
    <plugin filename="libroboticsgroup_gazebo_mimic_joint_plugin.so" name="mimic_right_j3a">
      <joint>right_hand_j3</joint>
      <mimicJoint>right_hand_j3a</mimicJoint>
      <multiplier>0.3</multiplier>
      <sensitiveness>0.0</sensitiveness>
    </plugin>
    <plugin filename="libroboticsgroup_gazebo_mimic_joint_plugin.so" name="mimic_right_j3b">
      <joint>right_hand_j3</joint>
      <mimicJoint>right_hand_j3b</mimicJoint>
      <multiplier>0.3</multiplier>
      <sensitiveness>0.0</sensitiveness>
    </plugin>
    <plugin filename="libroboticsgroup_gazebo_mimic_joint_plugin.so" name="mimic_right_j3c">
      <joint>right_hand_j3</joint>
      <mimicJoint>right_hand_j3c</mimicJoint>
      <multiplier>0.3</multiplier>
      <sensitiveness>0.0</sensitiveness>
    </plugin>
    <!-- j4 -->
    <plugin filename="libroboticsgroup_gazebo_mimic_joint_plugin.so" name="mimic_right_j4a">
      <joint>right_hand_j4</joint>
      <mimicJoint>right_hand_j4a</mimicJoint>
      <multiplier>0.3</multiplier>
      <sensitiveness>0.0</sensitiveness>
    </plugin>
    <plugin filename="libroboticsgroup_gazebo_mimic_joint_plugin.so" name="mimic_right_j4b">
      <joint>right_hand_j4</joint>
      <mimicJoint>right_hand_j4b</mimicJoint>
      <multiplier>0.3</multiplier>
      <sensitiveness>0.0</sensitiveness>
    </plugin>
    <plugin filename="libroboticsgroup_gazebo_mimic_joint_plugin.so" name="mimic_right_j4c">
      <joint>right_hand_j4</joint>
      <mimicJoint>right_hand_j4c</mimicJoint>
      <multiplier>0.3</multiplier>
      <sensitiveness>0.0</sensitiveness>
    </plugin>
  </gazebo>
  <transmission name="torso_j0_trans">
    <type>transmission_interface/SimpleTransmission</type>
    <joint name="torso_j0">
      <hardwareInterface>PositionJointInterface</hardwareInterface>
    </joint>
    <actuator name="torso_j0_motor">
      <hardwareInterface>PositionJointInterface</hardwareInterface>
      <mechanicalReduction>1</mechanicalReduction>
    </actuator>
  </transmission>
  <transmission name="torso_j1_trans">
    <type>transmission_interface/SimpleTransmission</type>
    <joint name="torso_j1">
      <hardwareInterface>PositionJointInterface</hardwareInterface>
    </joint>
    <actuator name="torso_j1_motor">
      <hardwareInterface>PositionJointInterface</hardwareInterface>
      <mechanicalReduction>1</mechanicalReduction>
    </actuator>
  </transmission>
  <transmission name="torso_j2_trans">
    <type>transmission_interface/SimpleTransmission</type>
    <joint name="torso_j2">
      <hardwareInterface>PositionJointInterface</hardwareInterface>
    </joint>
    <actuator name="torso_j2_motor">
      <hardwareInterface>PositionJointInterface</hardwareInterface>
      <mechanicalReduction>1</mechanicalReduction>
    </actuator>
  </transmission>
  <transmission name="zlift_j0_trans">
    <type>transmission_interface/SimpleTransmission</type>
    <joint name="zlift_j0">
      <hardwareInterface>PositionJointInterface</hardwareInterface>
    </joint>
    <actuator name="zlift_j0_motor">
      <hardwareInterface>PositionJointInterface</hardwareInterface>
      <mechanicalReduction>1</mechanicalReduction>
    </actuator>
  </transmission>
  <!-- ============================   Upper Arm   ============================ -->
  <!-- ============================   Forearm   ============================ -->
  <!-- <xacro:include filename="$(find meka_description)/transmissions/A2R4_l_arm_defs.transmission.xacro" />  -->
  <transmission name="right_hand_j0_trans">
    <type>transmission_interface/SimpleTransmission</type>
    <joint name="right_hand_j0">
      <hardwareInterface>PositionJointInterface</hardwareInterface>
    </joint>
    <actuator name="right_hand_j0_motor">
      <hardwareInterface>PositionJointInterface</hardwareInterface>
      <mechanicalReduction>1</mechanicalReduction>
    </actuator>
  </transmission>
  <transmission name="right_hand_j1_trans">
    <type>transmission_interface/SimpleTransmission</type>
    <joint name="right_hand_j1">
      <hardwareInterface>PositionJointInterface</hardwareInterface>
    </joint>
    <actuator name="right_hand_j1_motor">
      <hardwareInterface>PositionJointInterface</hardwareInterface>
      <mechanicalReduction>1</mechanicalReduction>
    </actuator>
  </transmission>
  <transmission name="right_hand_j2_trans">
    <type>transmission_interface/SimpleTransmission</type>
    <joint name="right_hand_j2">
      <hardwareInterface>PositionJointInterface</hardwareInterface>
    </joint>
    <actuator name="right_hand_j2_motor">
      <hardwareInterface>PositionJointInterface</hardwareInterface>
      <mechanicalReduction>1</mechanicalReduction>
    </actuator>
  </transmission>
  <transmission name="right_hand_j3_trans">
    <type>transmission_interface/SimpleTransmission</type>
    <joint name="right_hand_j3">
      <hardwareInterface>PositionJointInterface</hardwareInterface>
    </joint>
    <actuator name="right_hand_j3_motor">
      <hardwareInterface>PositionJointInterface</hardwareInterface>
      <mechanicalReduction>1</mechanicalReduction>
    </actuator>
  </transmission>
  <transmission name="right_hand_j4_trans">
    <type>transmission_interface/SimpleTransmission</type>
    <joint name="right_hand_j4">
      <hardwareInterface>PositionJointInterface</hardwareInterface>
    </joint>
    <actuator name="right_hand_j4_motor">
      <hardwareInterface>PositionJointInterface</hardwareInterface>
      <mechanicalReduction>1</mechanicalReduction>
    </actuator>
  </transmission>
  <!-- <xacro:include filename="$(find meka_description)/transmissions/H2R4_l_hand.transmission.xacro" />  -->
  <transmission name="head_j0_trans">
    <type>transmission_interface/SimpleTransmission</type>
    <joint name="head_j0">
      <hardwareInterface>PositionJointInterface</hardwareInterface>
    </joint>
    <actuator name="head_j0_motor">
      <hardwareInterface>PositionJointInterface</hardwareInterface>
      <mechanicalReduction>1</mechanicalReduction>
    </actuator>
  </transmission>
  <transmission name="head_j1_trans">
    <type>transmission_interface/SimpleTransmission</type>
    <joint name="head_j1">
      <hardwareInterface>PositionJointInterface</hardwareInterface>
    </joint>
    <actuator name="head_j1_motor">
      <hardwareInterface>PositionJointInterface</hardwareInterface>
      <mechanicalReduction>1</mechanicalReduction>
    </actuator>
  </transmission>
  <material name="GreyA">
    <!-- darkest -->
    <color rgba="0.3 0.3 0.3 1.0"/>
  </material>
  <material name="GreyB">
    <color rgba="0.5 0.5 0.5 1.0"/>
  </material>
  <material name="GreyC">
    <color rgba="0.7 0.7 0.7 1.0"/>
  </material>
  <!-- Shoulder pan -->
  <transmission name="right_arm_t0" type="pr2_mechanism_model/SimpleTransmission">
    <type>transmission_interface/SimpleTransmission</type>
    <actuator name="right_arm_a0"/>
    <joint name="right_arm_j0">
      <hardwareInterface>PositionJointInterface</hardwareInterface>
    </joint>
  </transmission>
  <!-- Shoulder lift -->
  <transmission name="right_arm_t1" type="pr2_mechanism_model/SimpleTransmission">
    <type>transmission_interface/SimpleTransmission</type>
    <actuator name="right_arm_a1"/>
    <joint name="right_arm_j1">
      <hardwareInterface>PositionJointInterface</hardwareInterface>
    </joint>
  </transmission>
  <!-- Upperarm roll: internal fixed attchment point for upper arm -->
  <transmission name="right_arm_t2" type="pr2_mechanism_model/SimpleTransmission">
    <type>transmission_interface/SimpleTransmission</type>
    <actuator name="right_arm_a2"/>
    <joint name="right_arm_j2">
      <hardwareInterface>PositionJointInterface</hardwareInterface>
    </joint>
  </transmission>
  <transmission name="right_arm_t3" type="pr2_mechanism_model/SimpleTransmission">
    <type>transmission_interface/SimpleTransmission</type>
    <actuator name="right_arm_a3">
      <hardwareInterface>PositionJointInterface</hardwareInterface>
    </actuator>
    <joint name="right_arm_j3">
      <hardwareInterface>PositionJointInterface</hardwareInterface>
    </joint>
    <mechanicalReduction>1</mechanicalReduction>
  </transmission>
  <!-- Elbow flex -->
  <transmission name="right_arm_t4" type="pr2_mechanism_model/SimpleTransmission">
    <type>transmission_interface/SimpleTransmission</type>
    <actuator name="right_arm_a4">
      <hardwareInterface>PositionJointInterface</hardwareInterface>
      <mechanicalReduction>1</mechanicalReduction>
    </actuator>
    <joint name="right_arm_j4">
      <hardwareInterface>PositionJointInterface</hardwareInterface>
    </joint>
  </transmission>
  <transmission name="right_arm_t5" type="pr2_mechanism_model/SimpleTransmission">
    <type>transmission_interface/SimpleTransmission</type>
    <actuator name="right_arm_a5">
      <hardwareInterface>PositionJointInterface</hardwareInterface>
      <mechanicalReduction>1</mechanicalReduction>
    </actuator>
    <joint name="right_arm_j5">
      <hardwareInterface>PositionJointInterface</hardwareInterface>
    </joint>
  </transmission>
  <!-- Wrist flex -->
  <transmission name="right_arm_t6" type="pr2_mechanism_model/SimpleTransmission">
    <type>transmission_interface/SimpleTransmission</type>
    <actuator name="right_arm_a6">
      <hardwareInterface>PositionJointInterface</hardwareInterface>
      <mechanicalReduction>1</mechanicalReduction>
    </actuator>
    <joint name="right_arm_j6">
      <hardwareInterface>PositionJointInterface</hardwareInterface>
    </joint>
  </transmission>
  <m3_l_arm_transmission parent="upper" reflect="1" side="l"/>
  <joint name="palm_joint_right" type="fixed">
    <origin rpy="0 0 0" xyz="0 0 -0.04414"/>
    <parent link="handmount_RIGHT"/>
    <child link="palm_right"/>
  </joint>
  <link name="palm_right">
    <inertial>
      <mass value="0.663"/>
      <origin xyz="0.001459 0.001619 -0.051312"/>
      <inertia ixx="0.000873" ixy="0.000031" ixz="-0.000008" iyy="0.000597" iyz="0.000016" izz="0.000565"/>
    </inertial>
    <visual>
      <material name="GreyC"/>
      <origin rpy="0 0 0 " xyz="0 0 0"/>
      <geometry name="palm_geom_right">
        <mesh filename="package://meka_description/meshes/mid_res/H2R3/H2R3_RT8_palm_right.dae"/>
      </geometry>
    </visual>
    <!-- meshes
      <collision>
	      <origin xyz="0 0 0" rpy="0.0 0.0 0.0 " />
	      <geometry name="palm_collision_right">
		      <mesh filename="package://${MESH_COLL}/H2R3/H2R3_RT8_palm_right.stl" />
	      </geometry>
      </collision>
      -->
    <!-- primitive only -->
    <collision>
      <origin rpy="0.0 0.0 0.0 " xyz="0.0112 0 -0.057"/>
      <geometry>
        <box size="0.04 0.0972 0.07"/>
      </geometry>
    </collision>
    <collision>
      <origin rpy="0.0 0.0 0.0 " xyz="0.02 -0.06 -0.030"/>
      <geometry>
        <box size="0.022 0.023 0.03"/>
      </geometry>
    </collision>
    <collision>
      <origin rpy="0.0 -0.5235 0.0 " xyz="-0.0058 0 -0.072"/>
      <geometry>
        <box size="0.025 0.0972 0.047"/>
      </geometry>
    </collision>
    <collision>
      <origin rpy="0 0 0.0 " xyz="0 0.0 -0.0166"/>
      <geometry>
        <cylinder length="0.0325" radius="0.02"/>
      </geometry>
    </collision>
    <collision>
      <origin rpy="1.5707 0 0.0 " xyz="0 -0.02 -0.05"/>
      <geometry>
        <cylinder length="0.0572" radius="0.03"/>
      </geometry>
    </collision>
    <collision>
      <origin rpy="1.5707 0 0.0 " xyz="-0.0023 0.0 -0.1"/>
      <geometry>
        <cylinder length="0.08" radius="0.013"/>
      </geometry>
    </collision>
    <collision>
      <origin rpy="0.0 0.0 0.0 " xyz="0.0 0.029 -0.015"/>
      <geometry>
        <box size="0.055 0.02 0.01"/>
      </geometry>
    </collision>
  </link>
  <joint name="fts_frame_joint_right" type="fixed">
    <parent link="handmount_RIGHT"/>
    <child link="m3loadx6_ma29_l0"/>
    <origin rpy="0.0 3.14159265359 0.0" xyz="0.0 0.0 -0.055"/>
  </joint>
  <link name="m3loadx6_ma29_l0"/>
  <!-- this defines TCP Tool Center Point as described in: https://groups.google.com/forum/m/#!topic/moveit-users/VB7VWsgV9-g -->
  <joint name="hand_right_tool_frame_joint" type="fixed">
    <parent link="handmount_RIGHT"/>
    <child link="hand_tool_frame_right"/>
    <origin rpy="-1.5708 0 1.5708" xyz="-0.02 0 -0.12"/>
  </joint>
  <link name="hand_tool_frame_right">
    <!-- This is the coordinate system of the end effector (this is the position
           used in IK); there is no actual arm part attached to this link -->
    <!-- The fake geometry here is only present to work around https://github.com/ros-planning/moveit_core/issues/158 -->
    <visual>
      <origin rpy="0 0 0" xyz="0 0 0"/>
      <geometry>
        <box size="0.01 0.01 0.01"/>
      </geometry>
      <material name="red"/>
    </visual>
    <collision>
      <origin rpy="0 0 0" xyz="0 0 -0.01"/>
      <geometry>
        <box size="0.001 0.001 0.001"/>
      </geometry>
      <material name="red"/>
    </collision>
    <inertial>
      <mass value="0.01"/>
      <origin xyz="0 0 0"/>
      <inertia ixx="0.0" ixy="0.0" ixz="0.0" iyy="0.0" iyz="0.0" izz="0.0"/>
    </inertial>
  </link>
  <!-- Start Thumb -->
  <joint name="right_hand_j0" type="revolute">
    <axis xyz="0 0 1"/>
    <origin rpy="0 0 -1.57079632679" xyz="-0.02 0.028 -0.03"/>
    <parent link="palm_right"/>
    <child link="thumb0_right"/>
    <limit effort="100" lower="0.0" upper="2.09439510239" velocity="0.349065850399"/>
  </joint>
  <link name="thumb0_right">
    <inertial>
      <mass value="0.0117"/>
      <origin xyz="0.0 0.0 0.0"/>
      <inertia ixx="0.0" ixy="0.0" ixz="0.0" iyy="0.0" iyz="0.0" izz="0.0"/>
    </inertial>
    <visual>
      <material name="GreyA"/>
      <origin rpy="0 0 0 " xyz="0 0 0"/>
      <geometry name="thumb0_geom_right">
        <mesh filename="package://meka_description/meshes/mid_res/H2R3/H2R3_RJ0_thumb_abductlink.dae"/>
      </geometry>
    </visual>
    <!-- meshes
      <collision>
	      <origin xyz="0 0 0" rpy="0.0 0.0 0.0 " />
	      <geometry name="thumb0_collision_right">
		      <mesh filename="package://${MESH_COLL}/H2R3/H2R3_RJ0_thumb_abductlink.stl" />
	      </geometry>
      </collision>
      -->
    <!-- primitive only -->
    <collision>
      <origin rpy="0.0 0 0.0 " xyz="0 0 0"/>
      <geometry>
        <cylinder length="0.0272" radius="0.0061"/>
      </geometry>
    </collision>
    <collision>
      <origin rpy="0.0 0.0 0.0 " xyz="-0.00945 -0.008 0"/>
      <geometry>
        <box size="0.0189 0.002 0.0190"/>
      </geometry>
    </collision>
    <collision>
      <origin rpy="0.0 0.0 0.0 " xyz="-0.00945 0.008 0"/>
      <geometry>
        <box size="0.0189 0.002 0.0190"/>
      </geometry>
    </collision>
    <collision>
      <origin rpy="1.5707 0 0.0 " xyz="-0.0189 0 0"/>
      <geometry>
        <cylinder length="0.018" radius="0.0095"/>
      </geometry>
    </collision>
  </link>
  <joint name="right_hand_j1" type="revolute">
    <axis xyz="0 1 0"/>
    <origin rpy="0 0 0" xyz="0 0 0"/>
    <parent link="palm_right"/>
    <child link="thumb_motor_right"/>
    <limit effort="100" lower="0.0" upper="2.96705972839" velocity="0.872664625997"/>
  </joint>
  <link name="thumb_motor_right">
    <inertial>
      <mass value="2e-06"/>
      <inertia ixx="1.1e-09" ixy="0" ixz="0" iyy="1.1e-09" iyz="0" izz="1.1e-09"/>
    </inertial>
  </link>
  <joint name="right_hand_j1a" type="revolute">
    <axis xyz="0 -1 0"/>
    <limit effort="100" lower="0.0" upper="1.4835298642" velocity="1.308996939"/>
    <origin rpy="0 0 0" xyz="-0.018 0 0"/>
    <parent link="thumb0_right"/>
    <child link="thumb1_right"/>
    <mimic joint="right_hand_j1" multiplier="0.4"/>
  </joint>
  <link name="thumb1_right">
    <inertial>
      <mass value="0.0344"/>
      <origin xyz="0.0 0.0 0.0"/>
      <inertia ixx="0.0" ixy="0.0" ixz="0.0" iyy="0.0" iyz="0.0" izz="0.0"/>
    </inertial>
    <visual>
      <material name="GreyB"/>
      <origin rpy="0 0 0 " xyz="0 0 0"/>
      <geometry name="thumb1_geom_right">
        <mesh filename="package://meka_description/meshes/mid_res/H2R3/H2R3_thumb_knuckle1.stl"/>
      </geometry>
    </visual>
    <!-- meshes
      <collision>
	      <origin xyz="0 0 0" rpy="0.0 0.0 0.0 " />
	      <geometry name="thumb1_collision_right">
		      <mesh filename="package://${MESH_COLL}/H2R3/H2R3_thumb_knuckle1.stl" />
	      </geometry>
      </collision>
             -->
    <!-- primitive only -->
    <collision>
      <origin rpy="0.0 0.0 0.0 " xyz="-0.022 0 -0.00134"/>
      <geometry>
        <box size="0.026 0.016 0.015"/>
      </geometry>
    </collision>
    <collision>
      <origin rpy="0.0 0.0 0.0 " xyz="-0.022 0 -0.00178"/>
      <geometry>
        <box size="0.023 0.011 0.019"/>
      </geometry>
    </collision>
    <collision>
      <origin rpy="1.5707 0 0.0 " xyz="0 0 0"/>
      <geometry>
        <cylinder length="0.011" radius="0.0115"/>
      </geometry>
    </collision>
  </link>
  <joint name="right_hand_j1b" type="revolute">
    <axis xyz="0 -1 0"/>
    <origin rpy="0 0 0" xyz="-0.044 0 0"/>
    <parent link="thumb1_right"/>
    <child link="thumb2_right"/>
    <limit effort="100" lower="0.0" upper="1.4835298642" velocity="0.872664625997"/>
    <mimic joint="right_hand_j1" multiplier="0.4"/>
  </joint>
  <link name="thumb2_right">
    <inertial>
      <mass value="0.01"/>
      <origin xyz="0.0 0.0 0.0"/>
      <inertia ixx="0.0" ixy="0.0" ixz="0.0" iyy="0.0" iyz="0.0" izz="0.0"/>
    </inertial>
    <visual>
      <material name="GreyC"/>
      <origin rpy="0 0 0 " xyz="0 0 0"/>
      <geometry name="thumb_knuckle2_geom_right">
        <mesh filename="package://meka_description/meshes/mid_res/H2R3/H2R3_thumb_knuckle2.dae"/>
      </geometry>
    </visual>
    <collision>
      <origin rpy="0.0 0.0 0.0 " xyz="0 0 0"/>
      <geometry name="thumb_knuckle2_collision_right">
        <mesh filename="package://meka_description/meshes/low_res/H2R3/H2R3_thumb_knuckle2convexhull.stl"/>
      </geometry>
    </collision>
  </link>
  <joint name="right_hand_thumb_dummy" type="fixed">
    <origin rpy="0 0 0" xyz="-0.035 0 0"/>
    <parent link="thumb2_right"/>
    <child link="thumb_tip_right"/>
  </joint>
  <link name="thumb_tip_right"/>
  <joint name="right_hand_j2" type="revolute">
    <axis xyz="0 1 0"/>
    <origin rpy="0 0 0" xyz="0 0 0"/>
    <parent link="palm_right"/>
    <child link="index_motor_right"/>
    <limit effort="100" lower="0.0" upper="5.23598775598" velocity="0.872664625997"/>
  </joint>
  <link name="index_motor_right">
    <inertial>
      <mass value="2e-06"/>
      <inertia ixx="1.1e-09" ixy="0" ixz="0" iyy="1.1e-09" iyz="0" izz="1.1e-09"/>
    </inertial>
  </link>
  <joint name="right_hand_j2a" type="revolute">
    <axis xyz="0 1 0"/>
    <origin rpy="0 0 0" xyz="0 0.028 -0.101"/>
    <parent link="palm_right"/>
    <child link="index0_right"/>
    <limit effort="100" lower="-0.123429684701" upper="0.647028460299" velocity="0.872664625997"/>
    <mimic joint="right_hand_j2" multiplier="0.3"/>
  </joint>
  <link name="index0_right">
    <inertial>
      <mass value="0.01"/>
      <origin xyz="0.0 0.0 0.0"/>
      <inertia ixx="0.0" ixy="0.0" ixz="0.0" iyy="0.0" iyz="0.0" izz="0.0"/>
    </inertial>
    <visual>
      <material name="GreyA"/>
      <origin rpy="0 0 0 " xyz="0 0 0"/>
      <geometry name="index0_geom_right">
        <mesh filename="package://meka_description/meshes/mid_res/H2R3/H2R3_finger_knuckle1.dae"/>
      </geometry>
    </visual>
    <!-- meshes   
      <collision>
	      <origin xyz="0 0 0" rpy="0.0 0.0 0.0 " />
	      <geometry name="index0_collision_right">
		      <mesh filename="package://${MESH_COLL}/H2R3/H2R3_finger_knuckle1.stl" />
	      </geometry>
      </collision>  -->
    <!-- primitive only -->
    <collision>
      <origin rpy="0.0 0.0 0.0 " xyz="-0.00134 0 -0.022"/>
      <geometry>
        <box size="0.015 0.016 0.026"/>
      </geometry>
    </collision>
    <collision>
      <origin rpy="0.0 0.0 0.0 " xyz="-0.00178 0 -0.022"/>
      <geometry>
        <box size="0.019 0.011 0.023"/>
      </geometry>
    </collision>
    <collision>
      <origin rpy="1.5707 0 0.0 " xyz="0 0 0"/>
      <geometry>
        <cylinder length="0.011" radius="0.0115"/>
      </geometry>
    </collision>
  </link>
  <joint name="right_hand_j2b" type="revolute">
    <axis xyz="0 1 0"/>
    <limit effort="100" lower="-0.610690705273" upper="0.610690705273" velocity="27.9252680319"/>
    <origin rpy="0 0 0" xyz="0 0 -0.044"/>
    <parent link="index0_right"/>
    <child link="index1_right"/>
    <mimic joint="right_hand_j2" multiplier="0.3"/>
  </joint>
  <link name="index1_right">
    <inertial>
      <mass value="0.0429"/>
      <origin xyz="0.0 0.0 0.0"/>
      <inertia ixx="0.0" ixy="0.0" ixz="0.0" iyy="0.0" iyz="0.0" izz="0.0"/>
    </inertial>
    <visual>
      <material name="GreyB"/>
      <origin rpy="0 0 0 " xyz="0 0 0"/>
      <geometry name="index1_geom_right">
        <mesh filename="package://meka_description/meshes/mid_res/H2R3/H2R3_finger_knuckle2.dae"/>
      </geometry>
    </visual>
    <!-- meshes 
      <collision>
	      <origin xyz="0 0 0" rpy="0.0 0.0 0.0 " />
	      <geometry name="index1_collision_right">
		      <mesh filename="package://${MESH_COLL}/H2R3/H2R3_finger_knuckle2.stl" />
	      </geometry>
      </collision>
      -->
    <!-- primitive only -->
    <collision>
      <origin rpy="0.0 0.0 0.0 " xyz="0.0 0 -0.015"/>
      <geometry>
        <box size="0.015 0.016 0.017"/>
      </geometry>
    </collision>
    <collision>
      <origin rpy="0.0 0.0 0.0 " xyz="-0.001 0 -0.015"/>
      <geometry>
        <box size="0.017 0.011 0.012"/>
      </geometry>
    </collision>
    <collision>
      <origin rpy="1.5707 0 0.0 " xyz="0 0 0"/>
      <geometry>
        <cylinder length="0.009" radius="0.01"/>
      </geometry>
    </collision>
  </link>
  <joint name="right_hand_j2c" type="revolute">
    <axis xyz="0 1 0"/>
    <limit effort="100" lower="-0.597077137107" upper="0.597129496985" velocity="27.9252680319"/>
    <origin rpy="0 0 0" xyz="0 0 -0.032"/>
    <parent link="index1_right"/>
    <child link="index2_right"/>
    <mimic joint="right_hand_j2" multiplier="0.3"/>
  </joint>
  <link name="index2_right">
    <inertial>
      <mass value="0.01"/>
      <origin xyz="0.0 0.0 0.0"/>
      <inertia ixx="0.0" ixy="0.0" ixz="0.0" iyy="0.0" iyz="0.0" izz="0.0"/>
    </inertial>
    <visual>
      <material name="GreyC"/>
      <origin rpy="0 0 0 " xyz="0 0 0"/>
      <geometry name="index2_geom_right">
        <mesh filename="package://meka_description/meshes/mid_res/H2R3/H2R3_finger_knuckle3.dae"/>
      </geometry>
    </visual>
    <collision>
      <origin rpy="0.0 0.0 0.0 " xyz="0 0 0"/>
      <geometry name="index2_collision_right">
        <mesh filename="package://meka_description/meshes/low_res/H2R3/H2R3_finger_knuckle3convexhull.stl"/>
      </geometry>
    </collision>
  </link>
  <joint name="right_hand_index_dummy" type="fixed">
    <origin rpy="0 0 0" xyz="0 0.008 -0.025"/>
    <parent link="index2_right"/>
    <child link="index_tip_right"/>
  </joint>
  <link name="index_tip_right"/>
  <joint name="right_hand_j3" type="revolute">
    <axis xyz="0 1 0"/>
    <origin rpy="0 0 0" xyz="0 0 0"/>
    <parent link="palm_right"/>
    <child link="ring_motor_right"/>
    <limit effort="100" lower="0.0" upper="5.23598775598" velocity="0.872664625997"/>
  </joint>
  <link name="ring_motor_right">
    <inertial>
      <mass value="2e-06"/>
      <inertia ixx="1.1e-09" ixy="0" ixz="0" iyy="1.1e-09" iyz="0" izz="1.1e-09"/>
    </inertial>
  </link>
  <joint name="right_hand_j3a" type="revolute">
    <axis xyz="0 1 0"/>
    <origin rpy="0 0 0" xyz="0 0 -0.101"/>
    <parent link="palm_right"/>
    <child link="ring0_right"/>
    <limit effort="100" lower="-0.123429684701" upper="0.647028460299" velocity="0.872664625997"/>
    <mimic joint="right_hand_j3" multiplier="0.3"/>
  </joint>
  <link name="ring0_right">
    <inertial>
      <mass value="0.01"/>
      <origin xyz="0.0 0.0 0.0"/>
      <inertia ixx="0.0" ixy="0.0" ixz="0.0" iyy="0.0" iyz="0.0" izz="0.0"/>
    </inertial>
    <visual>
      <material name="GreyA"/>
      <origin rpy="0 0 0 " xyz="0 0 0"/>
      <geometry name="ring0_geom_right">
        <mesh filename="package://meka_description/meshes/mid_res/H2R3/H2R3_finger_knuckle1.dae"/>
      </geometry>
    </visual>
    <!-- meshes     
      <collision>
	      <origin xyz="0 0 0" rpy="0.0 0.0 0.0 " />
	      <geometry name="ring0_collision_right">
		      <mesh filename="package://${MESH_COLL}/H2R3/H2R3_finger_knuckle1.stl" />
	      </geometry>
      </collision>     
      
       -->
    <!-- primitive only -->
    <collision>
      <origin rpy="0.0 0.0 0.0 " xyz="-0.00134 0 -0.022"/>
      <geometry>
        <box size="0.015 0.016 0.026"/>
      </geometry>
    </collision>
    <collision>
      <origin rpy="0.0 0.0 0.0 " xyz="-0.00178 0 -0.022"/>
      <geometry>
        <box size="0.019 0.011 0.023"/>
      </geometry>
    </collision>
    <collision>
      <origin rpy="1.5707 0 0.0 " xyz="0 0 0"/>
      <geometry>
        <cylinder length="0.011" radius="0.0115"/>
      </geometry>
    </collision>
  </link>
  <joint name="right_hand_j3b" type="revolute">
    <axis xyz="0 1 0"/>
    <limit effort="100" lower="-0.610690705273" upper="0.610690705273" velocity="27.9252680319"/>
    <origin rpy="0 0 0" xyz="0 0 -0.044"/>
    <parent link="ring0_right"/>
    <child link="ring1_right"/>
    <mimic joint="right_hand_j3" multiplier="0.3"/>
  </joint>
  <link name="ring1_right">
    <inertial>
      <mass value="0.0429"/>
      <origin xyz="0.0 0.0 0.0"/>
      <inertia ixx="0.0" ixy="0.0" ixz="0.0" iyy="0.0" iyz="0.0" izz="0.0"/>
    </inertial>
    <visual>
      <material name="GreyB"/>
      <origin rpy="0 0 0 " xyz="0 0 0"/>
      <geometry name="ring1_geom_right">
        <mesh filename="package://meka_description/meshes/mid_res/H2R3/H2R3_finger_knuckle2.dae"/>
      </geometry>
    </visual>
    <!-- meshes 
      <collision>
	      <origin xyz="0 0 0" rpy="0.0 0.0 0.0 " />
	      <geometry name="ring1_collision_right">
		      <mesh filename="package://${MESH_COLL}/H2R3/H2R3_finger_knuckle2.stl" />
	      </geometry>
      </collision>
      -->
    <!-- primitive only -->
    <collision>
      <origin rpy="0.0 0.0 0.0 " xyz="0.0 0 -0.015"/>
      <geometry>
        <box size="0.015 0.016 0.017"/>
      </geometry>
    </collision>
    <collision>
      <origin rpy="0.0 0.0 0.0 " xyz="-0.001 0 -0.015"/>
      <geometry>
        <box size="0.017 0.011 0.012"/>
      </geometry>
    </collision>
    <collision>
      <origin rpy="1.5707 0 0.0 " xyz="0 0 0"/>
      <geometry>
        <cylinder length="0.009" radius="0.01"/>
      </geometry>
    </collision>
  </link>
  <joint name="right_hand_j3c" type="revolute">
    <axis xyz="0 1 0"/>
    <limit effort="100" lower="-0.597077137107" upper="0.597129496985" velocity="27.9252680319"/>
    <origin rpy="0 0 0" xyz="0 0 -0.032"/>
    <parent link="ring1_right"/>
    <child link="ring2_right"/>
    <mimic joint="right_hand_j3" multiplier="0.3"/>
  </joint>
  <link name="ring2_right">
    <inertial>
      <mass value="0.01"/>
      <origin xyz="0.0 0.0 0.0"/>
      <inertia ixx="0.0" ixy="0.0" ixz="0.0" iyy="0.0" iyz="0.0" izz="0.0"/>
    </inertial>
    <visual>
      <material name="GreyC"/>
      <origin rpy="0 0 0 " xyz="0 0 0"/>
      <geometry name="ring2_geom_right">
        <mesh filename="package://meka_description/meshes/mid_res/H2R3/H2R3_finger_knuckle3.dae"/>
      </geometry>
    </visual>
    <collision>
      <origin rpy="0.0 0.0 0.0 " xyz="0 0 0"/>
      <geometry name="ring2_collision_right">
        <mesh filename="package://meka_description/meshes/low_res/H2R3/H2R3_finger_knuckle3convexhull.stl"/>
      </geometry>
    </collision>
  </link>
  <joint name="right_hand_ring_dummy" type="fixed">
    <origin rpy="0 0 0" xyz="0 0.008 -0.025"/>
    <parent link="ring2_right"/>
    <child link="ring_tip_right"/>
  </joint>
  <link name="ring_tip_right"/>
  <joint name="right_hand_j4" type="revolute">
    <axis xyz="0 1 0"/>
    <origin rpy="0 0 0" xyz="0 0 0"/>
    <parent link="palm_right"/>
    <child link="pinky_motor_right"/>
    <limit effort="100" lower="0.0" upper="5.23598775598" velocity="0.872664625997"/>
  </joint>
  <link name="pinky_motor_right">
    <inertial>
      <mass value="2e-06"/>
      <inertia ixx="1.1e-09" ixy="0" ixz="0" iyy="1.1e-09" iyz="0" izz="1.1e-09"/>
    </inertial>
  </link>
  <joint name="right_hand_j4a" type="revolute">
    <axis xyz="0 1 0"/>
    <origin rpy="0 0 0" xyz="0 -0.028 -0.101"/>
    <parent link="palm_right"/>
    <child link="pinky0_right"/>
    <limit effort="100" lower="-0.123429684701" upper="0.647028460299" velocity="0.872664625997"/>
    <mimic joint="right_hand_j4" multiplier="0.3"/>
  </joint>
  <link name="pinky0_right">
    <inertial>
      <mass value="0.01"/>
      <origin xyz="0.0 0.0 0.0"/>
      <inertia ixx="0.0" ixy="0.0" ixz="0.0" iyy="0.0" iyz="0.0" izz="0.0"/>
    </inertial>
    <visual>
      <material name="GreyA"/>
      <origin rpy="0 0 0 " xyz="0 0 0"/>
      <geometry name="pinky0_geom_right">
        <mesh filename="package://meka_description/meshes/mid_res/H2R3/H2R3_finger_knuckle1.dae"/>
      </geometry>
    </visual>
    <!-- meshes
      <collision>
	      <origin xyz="0 0 0" rpy="0.0 0.0 0.0 " />
	      <geometry name="pinky0_collision_right">
		      <mesh filename="package://${MESH_COLL}/H2R3/H2R3_finger_knuckle1.stl" />
	      </geometry>
      </collision> -->
    <!-- primitive only -->
    <collision>
      <origin rpy="0.0 0.0 0.0 " xyz="-0.00134 0 -0.022"/>
      <geometry>
        <box size="0.015 0.016 0.026"/>
      </geometry>
    </collision>
    <collision>
      <origin rpy="0.0 0.0 0.0 " xyz="-0.00178 0 -0.022"/>
      <geometry>
        <box size="0.019 0.011 0.023"/>
      </geometry>
    </collision>
    <collision>
      <origin rpy="1.5707 0 0.0 " xyz="0 0 0"/>
      <geometry>
        <cylinder length="0.011" radius="0.0115"/>
      </geometry>
    </collision>
  </link>
  <joint name="right_hand_j4b" type="revolute">
    <axis xyz="0 1 0"/>
    <limit effort="100" lower="-0.610690705273" upper="0.610690705273" velocity="27.9252680319"/>
    <origin rpy="0 0 0" xyz="0 0 -0.044"/>
    <parent link="pinky0_right"/>
    <child link="pinky1_right"/>
    <mimic joint="right_hand_j4" multiplier="0.3"/>
  </joint>
  <link name="pinky1_right">
    <inertial>
      <mass value="0.0429"/>
      <origin xyz="0.0 0.0 0.0"/>
      <inertia ixx="0.0" ixy="0.0" ixz="0.0" iyy="0.0" iyz="0.0" izz="0.0"/>
    </inertial>
    <visual>
      <material name="GreyB"/>
      <origin rpy="0 0 0 " xyz="0 0 0"/>
      <geometry name="pinky1_geom_right">
        <mesh filename="package://meka_description/meshes/mid_res/H2R3/H2R3_finger_knuckle2.dae"/>
      </geometry>
    </visual>
    <!-- meshes
      <collision>
	      <origin xyz="0 0 0" rpy="0.0 0.0 0.0 " />
	      <geometry name="pinky1_collision_right">
		      <mesh filename="package://${MESH_COLL}/H2R3/H2R3_finger_knuckle2.stl" />
	      </geometry>
      </collision>-->
    <!-- primitive only -->
    <collision>
      <origin rpy="0.0 0.0 0.0 " xyz="0.0 0 -0.015"/>
      <geometry>
        <box size="0.015 0.016 0.017"/>
      </geometry>
    </collision>
    <collision>
      <origin rpy="0.0 0.0 0.0 " xyz="-0.001 0 -0.015"/>
      <geometry>
        <box size="0.017 0.011 0.012"/>
      </geometry>
    </collision>
    <collision>
      <origin rpy="1.5707 0 0.0 " xyz="0 0 0"/>
      <geometry>
        <cylinder length="0.009" radius="0.01"/>
      </geometry>
    </collision>
  </link>
  <joint name="right_hand_j4c" type="revolute">
    <axis xyz="0 1 0"/>
    <limit effort="100" lower="-0.597077137107" upper="0.597129496985" velocity="27.9252680319"/>
    <origin rpy="0 0 0" xyz="0 0 -0.032"/>
    <parent link="pinky1_right"/>
    <child link="pinky2_right"/>
    <mimic joint="right_hand_j4" multiplier="0.3"/>
  </joint>
  <link name="pinky2_right">
    <inertial>
      <mass value="0.01"/>
      <origin xyz="0.0 0.0 0.0"/>
      <inertia ixx="0.0" ixy="0.0" ixz="0.0" iyy="0.0" iyz="0.0" izz="0.0"/>
    </inertial>
    <visual>
      <material name="GreyC"/>
      <origin rpy="0 0 0 " xyz="0 0 0"/>
      <geometry name="pinky2_geom_right">
        <mesh filename="package://meka_description/meshes/mid_res/H2R3/H2R3_finger_knuckle3.dae"/>
      </geometry>
    </visual>
    <collision>
      <origin rpy="0.0 0.0 0.0 " xyz="0 0 0"/>
      <geometry name="pinky2_collision_right">
        <mesh filename="package://meka_description/meshes/low_res/H2R3/H2R3_finger_knuckle3convexhull.stl"/>
      </geometry>
    </collision>
  </link>
  <joint name="right_hand_pinky_dummy" type="fixed">
    <origin rpy="0 0 0" xyz="0 0.008 -0.025"/>
    <parent link="pinky2_right"/>
    <child link="pinky_tip_right"/>
  </joint>
  <link name="pinky_tip_right"/>
  <m3_l_hand parent="handmount_LEFT" reflect="1" side="l" use_mimic="true">
    <origin rpy="0 0 0" xyz="0.0 0.0 0.0"/>
  </m3_l_hand>
  <joint name="head_j1" type="revolute">
    <axis xyz="0 0 1"/>
    <limit effort="100" lower="-0.977384381117" upper="0.977384381117" velocity="1.308996939"/>
    <origin rpy="0 0 0" xyz="0.0 0.0 0.2757"/>
    <!-- transform from parent link to this joint frame -->
    <parent link="upper"/>
    <child link="neck_pan"/>
    <child link="xtion"/>
  </joint>
  <link name="neck_pan">
    <inertial>
      <mass value="0.940"/>
      <origin xyz="0.000061 0.003310 0.028798"/>
      <inertia ixx="0.001395" ixy="-0.000000" ixz="-0.000000" iyy="0.001345" iyz="-0.000085" izz="0.000392"/>
    </inertial>
    <visual>
      <material name="GreyA"/>
      <origin rpy="0 0 0 " xyz="0 0 0"/>
      <geometry name="neck_tilt_geom">
        <!--<box size="0.01 0.01 0.01" />-->
        <!--<mesh filename="package://${MESH}/S2R1/S2R1_SH1_neckTilt.dae" />-->
        <mesh filename="package://meka_description/meshes/mid_res/S3R1/neck.stl"/>
      </geometry>
    </visual>
    <!-- meshes  
      <collision>
	      <origin xyz="0 0 0" rpy="0.0 0.0 0.0 " />
	      <geometry name="neck_tilt_geom_collison">
		      <mesh filename="package://${MESH}/S3R1/neck.stl" />
	      </geometry>
      </collision>
      -->
    <!-- primitive only -->
    <collision>
      <origin rpy="0.0 0.0 0.0 " xyz="0.0 0 0.00833"/>
      <geometry>
        <cylinder length="0.0166" radius="0.034"/>
      </geometry>
    </collision>
    <collision>
      <origin rpy="0.0 0.0 0.0 " xyz="0.0 0 0.0473"/>
      <geometry>
        <cylinder length="0.0614" radius="0.03"/>
      </geometry>
    </collision>
  </link>
  <joint name="head_j0" type="revolute">
    <axis xyz="0 -1 0"/>
    <origin rpy="0 0.314159265 0" xyz="0 0 0.1103"/>
    <parent link="neck_pan"/>
    <child link="shell"/>
    <limit effort="100" lower="-0.698131700798" upper="0.0349065850399" velocity="0.349065850399"/>
  </joint>
  <link name="shell">
    <inertial>
      <mass value="0.409"/>
      <origin xyz="0.0 0.0 0.0"/>
      <inertia ixx="0.0" ixy="0.0" ixz="0.0" iyy="0.0" iyz="0.0" izz="0.0"/>
    </inertial>
    <visual>
      <material name="GreyB"/>
      <origin rpy="0 0 0 " xyz="0 0 0"/>
      <geometry name="shell_geom">
        <mesh filename="package://meka_description/meshes/mid_res/S3R1/S3.dae"/>
      </geometry>
    </visual>
    <!-- meshes
      <collision>
	      <origin xyz="0 0 0" rpy="0.0 0.0 0.0 " />
	      <geometry name="S3_collision">
		      <box size="0.01 0.01 0.01" />
	      </geometry>
      </collision>
      -->
    <!-- primitive only -->
    <collision>
      <origin rpy="1.5708 0.0  0.0 " xyz="0.0 0 0.0"/>
      <geometry>
        <cylinder length="0.09" radius="0.0335"/>
      </geometry>
    </collision>
    <collision>
      <origin rpy="0.0 0.0 0.0 " xyz="0.005 0 0.07"/>
      <geometry>
        <box size="0.222 0.2 0.09"/>
      </geometry>
    </collision>
  </link>
  <joint name="head_xtion_dummy" type="revolute">
    <limit effort="100" lower="-0.977384381117" upper="0.977384381117" velocity="1.308996939"/>
    <origin rpy="-1.49304175558102 0.0465121191942754 -1.5830006092006217" xyz="0.0865 0.0095 0.0542"/>
    <axis xyz="0 0 1"/>
    <parent link="shell"/>
    <child link="_xtion_link"/>
  </joint>
  <link name="_xtion_link">
    <parent link="shell"/>
    <inertial>
      <mass value="0.1"/>
      <origin xyz="0.0 0.0 0.0"/>
      <inertia ixx="0.0" ixy="0.0" ixz="0.0" iyy="0.0" iyz="0.0" izz="0.0"/>
    </inertial>
  </link>
  <joint name="head_xtion_dummy2" type="revolute">
    <limit effort="100" lower="-0.977384381117" upper="0.977384381117" velocity="1.308996939"/>
    <origin rpy="0 -1.5708 1.5708" xyz="-0.04 0 0"/>
    <axis xyz="0 0 1"/>
    <parent link="_xtion_link"/>
    <child link="xtion_link"/>
  </joint>
  <link name="xtion_link">
    <parent link="_xtion_link"/>
    <inertial>
      <mass value="0.1"/>
      <origin xyz="0.0 0.0 0.0"/>
      <inertia ixx="0.0" ixy="0.0" ixz="0.0" iyy="0.0" iyz="0.0" izz="0.0"/>
    </inertial>
  </link>
  <!--joint name="head_j2" type="revolute">
      <axis xyz="0 -1 0" /> 
      <origin xyz="0.07975 0 0.123536" rpy="0 0 0" />
      <parent link="shell"/>
	<child link="BB2"/>
      <limit effort="100" velocity="${20.0*M_PI/180}" lower="${-40.0*M_PI/180}" upper="${2.0*M_PI/180}" />
    </joint>
    
    <link name="BB2">
      <inertial>
        <mass value="0.409" />
	<origin xyz="0.0 0.0 0.0"/>
	<inertia ixx="0.0"
	iyy="0.0"
	izz="0.0"
	ixy="0.0"
	ixz="0.0"
	iyz="0.0" />
      </inertial>

      <visual>
	      <material name="GreyB" />
	      <origin xyz="0 0 0" rpy="0 0 0 " />
	      <geometry name="shell_geom">
		      <mesh filename="package://${MESH}/S3R1/BB2.stl" />
	      </geometry>  
      </visual>
      
      <collision>
	      <origin xyz="-0.0141 0 0.0268" rpy="0.0 0.0 0.0 " />
	      <geometry name="S3_collision">
		      <box size="0.0474 0.157 0.037" />
	      </geometry>
      </collision>
    </link> -->
  <!-- Shoulder pan -->
  <joint name="right_arm_j0" type="revolute">
    <axis xyz="0 -1 0"/>
    <origin rpy="0 0 0" xyz="0.0 -0.18465 0.2337"/>
    <!-- transform from parent link to this joint frame -->
    <parent link="upper"/>
    <child link="shoulderupper_RIGHT"/>
    <limit effort="40" lower="-1.3962634016" upper="3.49065850399" velocity="0.523598775598"/>
    <dynamics damping="1.0"/>
  </joint>
  <link name="shoulderupper_RIGHT">
    <inertial>
      <mass value="2.0310"/>
      <origin xyz="-0.010946 0.025127 0.000022"/>
      <inertia ixx="0.003461" ixy="0.000428" ixz="0.000002" iyy="0.003097" iyz="0.000000" izz="0.005416"/>
    </inertial>
    <visual>
      <material name="GreyA"/>
      <origin rpy="0 0 0 " xyz="0 0 0"/>
      <geometry name="r_shoulder_geom">
        <mesh filename="package://meka_description/meshes/mid_res/A2R3/A2R3_RT1_shoulderRoll.dae"/>
      </geometry>
    </visual>
    <!-- meshes
      <collision>
	      <origin xyz="0 0 0" rpy="0.0 0.0 0.0 " />
	      <geometry name="r_shoulder_collision_geom">
		      <mesh filename="package://${MESH_COLL}/A2R3/A2R3_RT1_shoulderRoll.stl" />
	      </geometry>
      </collision> -->
    <!-- primitive only -->
    <collision>
      <origin rpy="0.0 0.0 0.0 " xyz="0.0 0.035 0.0"/>
      <geometry>
        <box size="0.128 0.07 0.072"/>
      </geometry>
    </collision>
    <collision>
      <origin rpy="0 1.5707 0.0 " xyz="-0.011 0.0 0"/>
      <geometry>
        <cylinder length="0.15" radius="0.036"/>
      </geometry>
    </collision>
  </link>
  <joint name="right_arm_j1" type="revolute">
    <axis xyz="-1 0 0"/>
    <limit effort="40" lower="-0.418879020479" upper="2.61799387799" velocity="0.523598775598"/>
    <origin rpy="0 0 0" xyz="0 0 0"/>
    <parent link="shoulderupper_RIGHT"/>
    <child link="shoulderpitch_RIGHT"/>
    <dynamics damping="1.0"/>
  </joint>
  <link name="shoulderpitch_RIGHT">
    <inertial>
      <mass value="0.566"/>
      <origin xyz="0.000944 -0.026331 -0.043257"/>
      <inertia ixx="0.000754" ixy="0.000015" ixz="0.000014" iyy="0.000921" iyz="0.000142" izz="0.000834"/>
    </inertial>
    <visual>
      <material name="GreyB"/>
      <origin rpy="0 0 0 " xyz="0 0 0"/>
      <geometry name="shoulderpitch_RIGHT">
        <mesh filename="package://meka_description/meshes/mid_res/A2R3/A2R3_RT2_shoulderPitch.dae"/>
      </geometry>
    </visual>
    <!-- meshes
      <collision>
	      <origin xyz="0 0 0" rpy="0.0 0.0 0.0 " />
	      <geometry name="shoulderpitch_RIGHT_collision">
		      <mesh filename="package://${MESH_COLL}/A2R3/A2R3_RT2_shoulderPitch.stl" />
	      </geometry>
      </collision>
      -->
    <!-- primitive only -->
    <collision>
      <origin rpy="-0.58 0.0 0.0 " xyz="0.0 -0.0256 -0.04"/>
      <geometry>
        <box size="0.09 0.07 0.072"/>
      </geometry>
    </collision>
    <collision>
      <origin rpy="0 0 0.0 " xyz="0 -0.0319 -0.0595"/>
      <geometry>
        <cylinder length="0.0262" radius="0.04"/>
      </geometry>
    </collision>
    <collision>
      <origin rpy="0 1.5707 0.0 " xyz="-0.0407 0.0 0"/>
      <geometry>
        <cylinder length="0.008" radius="0.0352"/>
      </geometry>
    </collision>
    <collision>
      <origin rpy="0 1.5707 0.0 " xyz="0.0407 0.0 0"/>
      <geometry>
        <cylinder length="0.008" radius="0.0352"/>
      </geometry>
    </collision>
  </link>
  <joint name="right_arm_j2" type="revolute">
    <axis xyz="0 0 -1"/>
    <origin rpy="0 0 0" xyz="0 -0.03175 -0.27857"/>
    <parent link="shoulderpitch_RIGHT"/>
    <child link="bicep_RIGHT"/>
    <limit effort="20" lower="-1.4835298642" upper="1.4835298642" velocity="0.872664625997"/>
    <dynamics damping="1.0"/>
  </joint>
  <link name="bicep_RIGHT">
    <inertial>
      <mass value="2.296"/>
      <origin xyz="-0.005767 0.084539 0.001385"/>
      <inertia ixx="0.013031" ixy="-0.000564" ixz="-0.000077" iyy="0.002070" iyz="0.000162" izz="0.013173"/>
    </inertial>
    <visual>
      <material name="GreyC"/>
      <origin rpy="0 0 0 " xyz="0.00502 0 0"/>
      <geometry name="bicep_RIGHT_geom">
        <mesh filename="package://meka_description/meshes/mid_res/A2R3/A2R3_RT3_bicep.dae"/>
      </geometry>
    </visual>
    <!-- meshes 
      <collision>
	      <origin xyz="0 0 0" rpy="0.0 0.0 0.0 " />
	      <geometry name="bicep_RIGHT_geom_collision">
		      <mesh filename="package://${MESH_COLL}/A2R3/A2R3_RT3_bicep.stl" />
	      </geometry>
      </collision> -->
    <!-- primitive only -->
    <collision>
      <origin rpy="0 0.0 0.0 " xyz="-0.03 0 0.1"/>
      <geometry>
        <box size="0.07 0.08 0.15"/>
      </geometry>
    </collision>
    <collision>
      <origin rpy="0 0 0.0 " xyz="-0.0047 0 0.15"/>
      <geometry>
        <cylinder length="0.12" radius="0.04"/>
      </geometry>
    </collision>
    <collision>
      <origin rpy="1.5707 0.0 0.0 " xyz="0 0.0 0"/>
      <geometry>
        <cylinder length="0.077" radius="0.0362"/>
      </geometry>
    </collision>
  </link>
  <joint name="right_arm_j3" type="revolute">
    <axis xyz="0 -1 0"/>
    <origin rpy="0 0 0" xyz="0.00502 0  0"/>
    <parent link="bicep_RIGHT"/>
    <child link="elbowclevis_RIGHT"/>
    <limit effort="20" lower="-0.00486908464063" upper="2.31810267927" velocity="0.872664625997"/>
    <dynamics damping="10.0"/>
  </joint>
  <link name="elbowclevis_RIGHT">
    <inertial>
      <mass value="0.223"/>
      <origin xyz="-0.000002 0.000278 -0.026124"/>
      <inertia ixx="0.000470" ixy="0.000000" ixz="0.000000" iyy="0.000233" iyz="0.000019" izz="0.000425"/>
    </inertial>
    <visual>
      <material name="GreyA"/>
      <origin rpy="0 0 0 " xyz="0 0 0"/>
      <geometry name="elbowclevis_RIGHT_geom">
        <mesh filename="package://meka_description/meshes/mid_res/A2R3/A2R3_RT4_elbow.dae"/>
      </geometry>
    </visual>
    <!-- meshes 
      <collision>
	      <origin xyz="0 0 0" rpy="0.0 0.0 0.0 " />
	      <geometry name="elbowclevis_RIGHT_collision">
		      <mesh filename="package://${MESH_COLL}/A2R3/A2R3_RT4_elbow.stl" />
	      </geometry>
      </collision> -->
    <!-- primitive only -->
    <collision>
      <origin rpy="0 0.0 0.0 " xyz="0 0 -0.048"/>
      <geometry>
        <box size="0.0712 0.0868 0.015"/>
      </geometry>
    </collision>
    <collision>
      <origin rpy="0 0 0.0 " xyz="0 0.0443 -0.024"/>
      <geometry>
        <box size="0.0652 0.01 0.048"/>
      </geometry>
    </collision>
    <collision>
      <origin rpy="0 0 0.0 " xyz="0 -0.046 -0.024"/>
      <geometry>
        <box size="0.0652 0.01 0.048"/>
      </geometry>
    </collision>
    <collision>
      <origin rpy="1.5707 0 0.0 " xyz="0 0.0443 0"/>
      <geometry>
        <cylinder length="0.01" radius="0.0356"/>
      </geometry>
    </collision>
    <collision>
      <origin rpy="1.5707 0 0.0 " xyz="0 -0.0485 0"/>
      <geometry>
        <cylinder length="0.015" radius="0.0356"/>
      </geometry>
    </collision>
  </link>
  <joint name="right_arm_j4" type="revolute">
    <axis xyz="0 0 -1"/>
    <limit effort="4" lower="-0.343829862643" upper="3.48542251623" velocity="2.61799387799"/>
    <origin rpy="0 0 0" xyz="0 0 -0.27747"/>
    <parent link="elbowclevis_RIGHT"/>
    <child link="wrist_RIGHT"/>
    <dynamics damping="1.0"/>
  </joint>
  <link name="wrist_RIGHT">
    <inertial>
      <mass value="1.468"/>
      <origin xyz="-0.004404 0.000124 0.130931"/>
      <inertia ixx="0.006099" ixy="0.000004" ixz="-0.000043" iyy="0.006120" iyz="0.000015" izz="0.001179"/>
    </inertial>
    <visual>
      <material name="GreyC"/>
      <origin rpy="0 0 0 " xyz="0 0 0"/>
      <geometry name="wrist_RIGHT_geom">
        <mesh filename="package://meka_description/meshes/mid_res/A2R3/A2R3_T5_forearmRoll.dae"/>
      </geometry>
    </visual>
    <!-- meshes
      <collision>
	      <origin xyz="0 0 0" rpy="0.0 0.0 0.0 " />
	      <geometry name="wrist_RIGHT_collision">
		      <mesh filename="package://${MESH_COLL}/A2R3/A2R3_T5_forearmRoll.stl" />
	      </geometry>
      </collision>
       -->
    <!-- primitive only -->
    <collision>
      <origin rpy="0 0.0 0.0 " xyz="0.0 0 0.1317"/>
      <geometry>
        <cylinder length="0.18" radius="0.041"/>
      </geometry>
    </collision>
    <collision>
      <origin rpy="0.0 0.0 0.0 " xyz="0 0.0307 0.025"/>
      <geometry>
        <box size="0.03 0.0154 0.05"/>
      </geometry>
    </collision>
    <collision>
      <origin rpy="0.0 0.0 0.0 " xyz="0 -0.0307 0.025"/>
      <geometry>
        <box size="0.03 0.0154 0.05"/>
      </geometry>
    </collision>
    <collision>
      <origin rpy="1.5707 0.0 0.0 " xyz="0 0.027 0"/>
      <geometry>
        <cylinder length="0.007" radius="0.024"/>
      </geometry>
    </collision>
    <collision>
      <origin rpy="1.5707 0.0 0.0 " xyz="0 -0.027 0"/>
      <geometry>
        <cylinder length="0.007" radius="0.024"/>
      </geometry>
    </collision>
  </link>
  <joint name="right_arm_j5" type="revolute">
    <dynamics damping="1.0"/>
    <axis xyz="0 -1 0"/>
    <origin rpy="0 0 0" xyz="0 0 0"/>
    <parent link="wrist_RIGHT"/>
    <child link="w_differential_RIGHT"/>
    <limit effort="8" lower="-1.02677719895" upper="1.02677719895" velocity="0.698131700798"/>
    <dynamics damping="1.0"/>
  </joint>
  <link name="w_differential_RIGHT">
    <inertial>
      <mass value="0.278"/>
      <origin xyz="0 0 0"/>
      <inertia ixx="0" ixy="0" ixz="0" iyy="0" iyz="0" izz="0"/>
    </inertial>
    <visual>
      <material name="GreyB"/>
      <origin rpy="0 0 0 " xyz="0 0 0"/>
      <geometry name="w_differential_RIGHT_geom">
        <mesh filename="package://meka_description/meshes/mid_res/A2R3/A2R3_T6_wristDiff.dae"/>
      </geometry>
    </visual>
    <collision>
      <origin rpy="1.5707 0.0 0.0" xyz="0 0 0"/>
      <geometry name="w_differential_RIGHT_collision">
        <cylinder length="0.044" radius="0.027"/>
      </geometry>
    </collision>
  </link>
  <joint name="right_arm_j6" type="revolute">
    <axis xyz="-1 0 0"/>
    <limit effort="8" lower="-1.0471975512" upper="1.0471975512" velocity="0.698131700798"/>
    <origin rpy="0 0 0" xyz="0 0 0"/>
    <parent link="w_differential_RIGHT"/>
    <child link="handmount_RIGHT"/>
    <dynamics damping="1.0"/>
  </joint>
  <link name="handmount_RIGHT">
    <inertial>
      <mass value="0.093"/>
      <origin xyz="0 0 0"/>
      <inertia ixx="0" ixy="0" ixz="0" iyy="0" iyz="0" izz="0"/>
    </inertial>
    <visual>
      <material name="GreyA"/>
      <origin rpy="0 0 0 " xyz="0 0 0"/>
      <geometry name="handmount_RIGHT_geom">
        <mesh filename="package://meka_description/meshes/mid_res/A2R3/A2R3_T7_wristYaw.dae"/>
      </geometry>
    </visual>
    <!-- meshes
      <collision>
	      <origin xyz="0 0 0" rpy="0.0 0.0 0.0 " />
	      <geometry name="handmount_RIGHT_collision">
		      <mesh filename="package://${MESH_COLL}/A2R3/A2R3_T7_wristYaw.stl" />
	      </geometry>
      </collision>
       -->
    <!-- primitive only -->
    <collision>
      <origin rpy="0.0 0.0 0.0 " xyz="0 0 -0.043"/>
      <geometry>
        <box size="0.04 0.0412 0.004"/>
      </geometry>
    </collision>
    <collision>
      <origin rpy="0 1.1 0.0" xyz="-0.025 0.0 -0.0302"/>
      <geometry>
        <box size="0.03 0.03 0.004"/>
      </geometry>
    </collision>
    <collision>
      <origin rpy="0 2.04 0.0" xyz="0.025 0.0 -0.0302"/>
      <geometry>
        <box size="0.03 0.03 0.004"/>
      </geometry>
    </collision>
    <collision>
      <origin rpy="0 1.5707 0.0" xyz="-0.0275 0.0 0"/>
      <geometry>
        <cylinder length="0.014" radius="0.0206"/>
      </geometry>
    </collision>
    <collision>
      <origin rpy="0 1.5707 0.0" xyz="0.0275 0.0 0"/>
      <geometry>
        <cylinder length="0.014" radius="0.0206"/>
      </geometry>
    </collision>
  </link>
  <m3_l_arm parent="upper" reflect="1" side="l">
    <origin rpy="0 0 0" xyz="0.0 0.18465 0.2337"/>
  </m3_l_arm>
  <link name="base_link"/>
  <joint name="fixed_base_joint" type="fixed">
    <origin rpy="0 0 0" xyz="0.0 0.0 0.0"/>
    <child link="fixed_base"/>
    <parent link="base_link"/>
  </joint>
  <link name="fixed_base">
    <inertial>
      <origin rpy="0 0 0" xyz="0 0 0.25"/>
      <mass value="100.0"/>
      <inertia ixx="3.41666666667" ixy="0.0" ixz="0.0" iyy="5.08333333333" iyz="0.0" izz="4.33333333333"/>
    </inertial>
    <visual>
      <material name="GreyC"/>
      <origin rpy="0 0 0" xyz="0 0 0"/>
      <geometry name="b1r1_3_geom">
        <mesh filename="package://meka_description/meshes/mid_res/B1R1/meka_mobile_base+backpack.dae"/>
        <!-- B1R1/MB1_00_000_meka_mobile_base+backpack+zlift.dae -->
      </geometry>
    </visual>
    <visual>
      <material name="GreyC"/>
      <origin rpy="0 0 0" xyz="0.17654 0 0.32141"/>
      <geometry name="b1r1_3_geom">
        <mesh filename="package://meka_description/meshes/mid_res/B1R1/meka_zlift.dae"/>
        <!-- B1R1/MB1_00_000_meka_mobile_base+backpack+zlift.dae -->
      </geometry>
    </visual>
    <collision>
      <origin rpy="0.0 0.0 0.0 " xyz="0 0 0.2"/>
      <geometry>
        <box size="0.46 0.46 0.25"/>
      </geometry>
    </collision>
    <collision>
      <origin rpy="0.0 0.0 0.0 " xyz="0 0 0.2"/>
      <geometry>
        <box size="0.68 0.27 0.25"/>
      </geometry>
    </collision>
    <collision>
      <origin rpy="0.0 0.0 0.0 " xyz="0.23 0.12 0.165"/>
      <geometry>
        <cylinder length="0.325" radius="0.11"/>
      </geometry>
    </collision>
    <collision>
      <origin rpy="0.0 0.0 0.0 " xyz="0.23 -0.12 0.165"/>
      <geometry>
        <cylinder length="0.325" radius="0.11"/>
      </geometry>
    </collision>
    <collision>
      <origin rpy="0.0 0.0 0.0 " xyz="-0.23 0.12 0.275"/>
      <geometry>
        <cylinder length="0.55" radius="0.11"/>
        <!-- l 0.48 -->
      </geometry>
    </collision>
    <collision>
      <origin rpy="0.0 0.0 0.0 " xyz="-0.23 -0.12 0.275"/>
      <geometry>
        <cylinder length="0.55" radius="0.11"/>
        <!-- l 0.48 -->
      </geometry>
    </collision>
    <collision>
      <origin rpy="0.0 0.0 0.0 " xyz="-0.13 0 0.4375"/>
      <geometry>
        <box size="0.20 0.46 0.225"/>
      </geometry>
    </collision>
    <collision>
      <origin rpy="0.0 0.0 0.0 " xyz="-0.23 0 0.4375"/>
      <geometry>
        <box size="0.22 0.27 0.225"/>
      </geometry>
    </collision>
    <!-- zlift -->
    <collision>
      <origin rpy="0.0 0.0 0.0 " xyz="0.06 0 0.95"/>
      <geometry>
        <box size="0.22 0.1 1.2"/>
      </geometry>
    </collision>
  </link>
  <joint name="zlift_j0" type="prismatic">
    <axis xyz="0 0 1"/>
    <origin rpy="0 0 0" xyz="0.17513 0.0 0.43"/>
    <!-- transform from parent link to this joint frame -->
    <parent link="base_link"/>
    <child link="zlift_link"/>
    <limit effort="30" lower="0.0" upper="0.699999203097" velocity="34.8"/>
    <!-- !!! this should be changed at some point !!! -->
    <dynamics damping="10.0"/>
    <!--safety_controller k_position="100" k_velocity="10"
                         soft_lower_limit="${reflect*M_PI/4-1.5+0.15}"
                         soft_upper_limit="${reflect*M_PI/4+1.5-0.15}" /-->
  </joint>
  <link name="zlift_link">
    <inertial>
      <mass value="25.799322"/>
      <origin rpy="0 0 0" xyz="0.0 0.0 0.0"/>
      <inertia ixx="0.866179142480" ixy="-0.06086507933" ixz="-0.12118061183" iyy="0.87421714893" iyz="-0.05886609911" izz="0.27353821674"/>
    </inertial>
    <visual>
      <material name="GreyA"/>
      <origin rpy="0 0 0 " xyz="0 0 0"/>
      <geometry name="z_lift_geom">
        <mesh filename="package://meka_description/meshes/mid_res/B1R1/meka_festo-chest_mount_assy.dae"/>
      </geometry>
    </visual>
    <!-- meshes 
      <collision>
	      <origin xyz="0 0 0" rpy="0.0 0.0 0.0 " />
	      <geometry name="z_lift_geom_collision_geom">
		      <mesh filename="package://${MESH_COLL}/B1R1/MB1_00_011_festo-chest_mount_assy+spacer.stl" />
	      </geometry>
      </collision>-->
    <!-- primitive meshes only -->
    <collision>
      <origin rpy="0.0 0.0 0.0 " xyz="0.108 0 0.035"/>
      <geometry>
        <box size="0.2 0.21 0.07"/>
      </geometry>
    </collision>
    <collision>
      <origin rpy="0.0 0.0 0.0 " xyz="0.004 0 0.09"/>
      <geometry>
        <box size="0.008 0.08 0.18"/>
      </geometry>
    </collision>
  </link>
  <!--link name="upper">
	  <inertial>
		  <mass value="1000" />
		  <origin xyz="0 0 0" />
		  <inertia ixx="1000"  ixy="0"  ixz="0" iyy="1000" iyz="0" izz="1000" />
	  </inertial>
	  <visual>
		  <material name="GreyC" />
		  <origin xyz="0 0 0" rpy="0 0 0" />
		  <geometry name="upper_geom">
			  <mesh filename="package://${MESH}/A2R3/A2R3_T4_Chest_Neck.dae" />
		  </geometry>
		  <material name="Blue" />
	  </visual>
	  <collision>
		  <origin xyz="0 0 0" rpy="0.0 0.0 0.0 " />
		  <geometry name="upper_collision_geom">
			  <mesh filename="package://${MESH_COLL}/A2R3/A2R3_T4_Chest_Neck.stl" />
		  </geometry>
	  </collision>
  </link -->
  <!--joint name="chest_joint" type="fixed">
	<origin xyz="0 0 -0.03" rpy="0 0 0" />
	<parent link="zlift_link" />
	<child link="upper" />
    </joint-->
  <!--joint name="origin_joint" type="fixed">
	<origin xyz="0 0 0.2337" rpy="0 0 0" />
	<parent link="upper" />
	<child link="T0" />
    </joint-->
  <!--link name="T0"/-->
  <!-- Solid Base -->
  <joint name="chest_joint" type="fixed">
    <origin rpy="0 0 0" xyz="0.263 0.0 0.006"/>
    <parent link="zlift_link"/>
    <child link="panplate"/>
  </joint>
  <link name="panplate">
    <inertial>
      <mass value="30"/>
      <origin xyz="0 0 0"/>
      <inertia ixx="1" ixy="0" ixz="0" iyy="1" iyz="0" izz="1"/>
    </inertial>
    <visual>
      <material name="GreyA"/>
      <origin rpy="0 0 0 " xyz="0 0 0"/>
      <geometry name="panplate_geom">
        <mesh filename="package://meka_description/meshes/mid_res/T2R3/T2R3_TJ0_base.dae"/>
      </geometry>
    </visual>
    <!-- meshes  
    <collision>
      <origin xyz="0 0 0" rpy="0.0 0.0 0.0 " />
      <geometry name="base_collision_geom">
        <mesh filename="package://${MESH_COLL}/T2R3/T2R3_TJ0_base.stl" />
      </geometry>
    </collision>-->
    <!-- primitive only -->
    <collision>
      <origin rpy="0.0 0.0 0.0 " xyz="-0.11 0 0.025"/>
      <geometry>
        <box size="0.22 0.19 0.05"/>
      </geometry>
    </collision>
    <collision>
      <origin rpy="0.0 0.0 0.0 " xyz="0.0 0 0.05"/>
      <geometry>
        <cylinder length="0.1" radius="0.095"/>
      </geometry>
    </collision>
  </link>
  <joint name="torso_j0" type="revolute">
    <axis xyz="0 0 1"/>
    <origin rpy="0 0 0" xyz="0 0 0.1658"/>
    <parent link="panplate"/>
    <child link="torso"/>
    <limit effort="25" lower="-2.09439510239" upper="2.09439510239" velocity="0.436332312999"/>
    <dynamics damping="1.0"/>
  </joint>
  <link name="torso">
    <inertial>
      <mass value="4.411"/>
      <origin xyz="0.00011774 0.0038073 -0.0522753"/>
      <inertia ixx="0.026360" ixy="-0.0000024" ixz="-0.0000508" iyy="0.0134266" iyz="0.0006839" izz="0.0229879"/>
    </inertial>
    <visual>
      <material name="GreyC"/>
      <origin rpy="0 0 0 " xyz="0 0 0"/>
      <geometry name="torso_geom">
        <mesh filename="package://meka_description/meshes/mid_res/T2R3/T2R3_TJ1_pan.dae"/>
      </geometry>
    </visual>
    <!-- meshes  
    <collision>
      <origin xyz="0 0 0" rpy="0.0 0.0 0.0 " />
      <geometry name="torso_collision_geom">
        <mesh filename="package://${MESH_COLL}/T2R3/T2R3_TJ1_pan.stl" />
      </geometry>
    </collision>
    -->
    <!-- primitive only -->
    <collision>
      <origin rpy="0.0 0.0 0.0 " xyz="0.0 0 -0.0615"/>
      <geometry>
        <cylinder length="0.015" radius="0.088"/>
      </geometry>
    </collision>
    <collision>
      <origin rpy="0.0 0.0 0.0 " xyz="0.0 0 -0.0615"/>
      <geometry>
        <box size="0.08 0.23 0.015"/>
      </geometry>
    </collision>
    <collision>
      <origin rpy="1.5707 0.0 0.0 " xyz="0.0 0.105 0"/>
      <geometry>
        <cylinder length="0.02" radius="0.052"/>
      </geometry>
    </collision>
    <collision>
      <origin rpy="1.5707 0.0 0.0  " xyz="0.0 -0.105 0"/>
      <geometry>
        <cylinder length="0.02" radius="0.052"/>
      </geometry>
    </collision>
  </link>
  <joint name="torso_j1" type="revolute">
    <axis xyz="0 1 0"/>
    <origin rpy="0 0 0" xyz="0 0 0"/>
    <parent link="torso"/>
    <child link="mid"/>
    <limit effort="200" lower="-0.205835230801" upper="0.930146870379" velocity="0.174532925199"/>
    <dynamics damping="1.0"/>
  </joint>
  <link name="mid">
    <inertial>
      <mass value="4.934"/>
      <origin xyz="0.001179 -0.002993 0.046259"/>
      <inertia ixx="0.041106" ixy="0.000135" ixz="0.000505" iyy="0.026009" iyz="0.002396" izz="0.025902"/>
    </inertial>
    <visual>
      <material name="GreyB"/>
      <origin rpy="0 0 0" xyz="0 0 0"/>
      <geometry name="mid_geom">
        <mesh filename="package://meka_description/meshes/mid_res/T2R3/T2R3_TJ2.dae"/>
      </geometry>
    </visual>
    <!-- meshes  
    <collision>
      <origin xyz="0 0 0" rpy="0.0 0.0 0.0 " />
      <geometry name="mid_collision_geom">
        <mesh filename="package://${MESH_COLL}/T2R3/T2R3_TJ2.stl" />
      </geometry>
    </collision>
    -->
    <!-- primitive only -->
    <collision>
      <origin rpy="0.0 0.0 0.0 " xyz="0.0 0 0.0684"/>
      <geometry>
        <box size="0.114 0.241 0.1368"/>
      </geometry>
    </collision>
    <collision>
      <origin rpy="1.5707 0.0 0.0 " xyz="0.0 0.0 0"/>
      <geometry>
        <cylinder length="0.241" radius="0.057"/>
      </geometry>
    </collision>
    <collision>
      <origin rpy="1.5707 0.0 0.0 " xyz="0.0 0.0 0.1368"/>
      <geometry>
        <cylinder length="0.241" radius="0.057"/>
      </geometry>
    </collision>
  </link>
  <joint name="torso_j2" type="revolute">
    <axis xyz="0 1 0"/>
    <origin rpy="0 0 0" xyz="0 0 0.1397"/>
    <parent link="mid"/>
    <child link="upper"/>
    <limit effort="200" lower="-0.205835230801" upper="0.930146870379" velocity="0.174532925199"/>
    <dynamics damping="1.0"/>
    <mimic joint="torso_j1" multiplier="1.0"/>
  </joint>
  <link name="upper">
    <inertial>
      <mass value="6.534"/>
      <origin xyz="0.008700 0.011470 0.129740"/>
      <inertia ixx="0.069760" ixy="-0.000400" ixz="0.001300" iyy="0.048010" iyz="0.005100" izz="0.040590"/>
    </inertial>
    <visual>
      <material name="GreyC"/>
      <origin rpy="0 0 0" xyz="0 0 0"/>
      <geometry name="upper_geom">
        <mesh filename="package://meka_description/meshes/mid_res/A2R3/A2R3_T4_Chest.dae"/>
      </geometry>
    </visual>
    <!-- meshes 
    <collision>
      <origin xyz="0 0 0" rpy="0.0 0.0 0.0 " />
      <geometry name="upper_collision_geom">
        <mesh filename="package://${MESH_COLL}/T2R3/T2R3_TJ3_chest_waist_neck.stl" />
      </geometry>
    </collision>
        -->
    <!-- primitive only -->
    <collision>
      <origin rpy="0.0 0.0 0.0 " xyz="0.0 0 0.1346"/>
      <geometry>
        <box size="0.14 0.22 0.1978"/>
      </geometry>
    </collision>
    <collision>
      <origin rpy="1.5707 0.0 0.0 " xyz="0.0 0.0 0.2335"/>
      <geometry>
        <cylinder length="0.22" radius="0.0644"/>
      </geometry>
    </collision>
  </link>
  <joint name="xtion_sim_joint" type="fixed">
    <origin rpy="0 0 0" xyz="0.12 0 0.06"/>
    <parent link="shell"/>
    <child link="xtion_sim_link"/>
  </joint>
  <link name="xtion_sim_link">
    <inertial>
      <mass value="0.200"/>
      <origin rpy="0 0 0" xyz="0 0 0"/>
      <inertia ixx="5.8083e-4" ixy="0" ixz="0" iyy="3.0833e-5" iyz="0" izz="5.9083e-4"/>
    </inertial>
    <visual>
      <origin rpy="0 0 0" xyz="0 0 0"/>
      <geometry>
        <mesh filename="package://tobi_world_misc/meshes/asus_camera/asus_camera_simple.dae"/>
      </geometry>
    </visual>
    <collision>
      <origin rpy="0 0 0" xyz="0 0 0"/>
      <geometry>
        <box size="0.035 0.185 0.025"/>
      </geometry>
    </collision>
  </link>
  <joint name="xtion_sim_depth_joint" type="fixed">
    <origin rpy="0 0 0" xyz="0.0 0.049 0.0"/>
    <parent link="xtion_sim_link"/>
    <child link="xtion_sim_depth_frame"/>
  </joint>
  <link name="xtion_sim_depth_frame"/>
  <joint name="xtion_sim_depth_optical_joint" type="fixed">
    <origin rpy="-1.57079632679 0.0 -1.57079632679" xyz="0 0 0"/>
    <parent link="xtion_sim_depth_frame"/>
    <child link="xtion_sim_depth_optical_frame"/>
  </joint>
  <link name="xtion_sim_depth_optical_frame"/>
  <joint name="xtion_sim_rgb_joint" type="fixed">
    <origin rpy="0 0 0" xyz="0.0 0.022 0.0"/>
    <parent link="xtion_sim_link"/>
    <child link="xtion_sim_rgb_frame"/>
  </joint>
  <link name="xtion_sim_rgb_frame"/>
  <joint name="xtion_sim_rgb_optical_joint" type="fixed">
    <origin rpy="-1.57079632679 0.0 -1.57079632679" xyz="0 0 0"/>
    <parent link="xtion_sim_rgb_frame"/>
    <child link="xtion_sim_rgb_optical_frame"/>
  </joint>
  <link name="xtion_sim_rgb_optical_frame"/>
  <!-- ASUS Xtion PRO camera for simulation -->
  <gazebo reference="xtion_sim_depth_frame">
    <sensor name="xtion_sim" type="depth">
      <noise>
        <type>gaussian</type>
        <mean>0.0</mean>
        <stddev>2</stddev>
      </noise>
      <update_rate>20</update_rate>
      <camera>
        <horizontal_fov>1.09606677025</horizontal_fov>
        <image>
          <format>R8B8G8</format>
          <width>640</width>
          <height>480</height>
        </image>
        <clip>
          <near>0.5</near>
          <far>9</far>
        </clip>
        <noise>
          <type>gaussian</type>
          <mean>0.1</mean>
          <stddev>0.07</stddev>
        </noise>
      </camera>
      <plugin filename="libgazebo_ros_openni_kinect.so" name="xtion_sim_camera_controller">
        <alwaysOn>true</alwaysOn>
        <updateRate>20</updateRate>
        <imageTopicName>xtion_sim/rgb/image_raw</imageTopicName>
        <cameraInfoTopicName>xtion_sim/rgb/camera_info</cameraInfoTopicName>
        <depthImageTopicName>xtion_sim/depth/image_raw</depthImageTopicName>
        <depthImageCameraInfoTopicName>xtion_sim/depth/camera_info</depthImageCameraInfoTopicName>
        <pointCloudTopicName>xtion_sim/depth/points</pointCloudTopicName>
        <frameName>xtion_sim_depth_optical_frame</frameName>
        <distortion_k1>0.0</distortion_k1>
        <distortion_k2>0.0</distortion_k2>
        <distortion_k3>0.0</distortion_k3>
        <distortion_t1>0.0</distortion_t1>
        <distortion_t2>0.0</distortion_t2>
      </plugin>
    </sensor>
  </gazebo>
  <!-- Extra Wheels -->
  <!-- <xacro:include filename="$(find meka_description)/urdf/wheel_defs.urdf.xacro" />

  <wheel fb="front" lr="right" parent="base_link" translateX="1" translateY="-1" flipY="-1"/>
  <wheel fb="front" lr="left" parent="base_link" translateX="1" translateY="1" flipY="-1"/>
  <wheel fb="back" lr="right" parent="base_link" translateX="-1" translateY="-1" flipY="-1"/>
  <wheel fb="back" lr="left" parent="base_link" translateX="-1" translateY="1" flipY="-1"/> -->
</robot>

